Workbook
Name ______XL19: #REF!
Name ______XL19: #REF!
Name _____XL19: #REF!
Name _____XL19: #REF!
Name ____XL19: #REF!
Name ____XL19: #REF!
Name ___XL19: #REF!
Name ___XL19: #REF!
Name __WD10: #REF!
Name __WD10: #REF!
Name __XL19: #REF!
Name __XL19: #REF!
Name _Lim19: #REF!
Name _Lim19: #REF!
Name _Lim19: #REF!
Name _WD10: #REF!
Name _WD10: #REF!
Name Aๅ: #REF!
Name Aๅ: #REF!
Name FYC: #REF!
Name FYC: #REF!
Name FYC: #REF!
Name FYC_DPO: #REF!
Name FYC_DPO: #REF!
Name FYC_DPO: #REF!
Name FYC_DPO_AL: #REF!
Name FYC_DPO_AL: #REF!
Name FYC_DPO_AL: #REF!
Name FYC_Life: #REF!
Name FYC_Life: #REF!
Name FYC_Life: #REF!
Name FYC_PA: #REF!
Name FYC_PA: #REF!
Name FYC_PA: #REF!
Name FYC_PV: #REF!
Name FYC_PV: #REF!
Name FYC_PV: #REF!
Name FYC_PV12: #REF!
Name FYC_PV12: #REF!
Name FYC_PV12: #REF!
Name FYP_PV: #REF!
Name FYP_PV: #REF!
Name FYP_PV: #REF!
Name FYP_PV12: #REF!
Name FYP_PV12: #REF!
Name FYP_PV12: #REF!
Name Income: #REF!
Name Income: #REF!
Name Income: #REF!
Name Lim19pcn: #REF!
Name Lim19pcn: #REF!
Name Lim19pcn: #REF!
Name Num_Pmt_Per_Year: '[1]Int.-Bank3'!#REF!
Name Num_Pmt_Per_Year: '[1]Int.-Bank3'!#REF!
Name Num_Pmt_Per_Year: '[1]Int.-Bank3'!#REF!
Name Pay_Num: '[1]Int.-Bank3'!#REF!
Name Pay_Num: '[1]Int.-Bank3'!#REF!
Name Pay_Num: '[1]Int.-Bank3'!#REF!
Name Ratetable: #REF!
Name Ratetable: #REF!

Sheet COM
A1: แบบประกัน | B1: =VLOOKUP($D$1,$H$3:$I$39,2,0) -> สุพรีม ไลฟ์ โพรเทคเตอร์ A90/20 | C1: 1 | D1: 29 | E1: =VLOOKUP($D$1,$H$3:$J$39,3,0) -> 20SLPA | F1: =VLOOKUP($D$1,$H$3:$K$39,4,0) -> 0.75 | H1: ลำดับ | I1: แบบประกัน | J1: Code | K1: นับผลงาน | L1: Commission
A2: 1 | B2: =VLOOKUP($B$1,$I$3:$U$39,C2,0) -> 0.4 | C2: 4 | L2: 1 | M2: 2 | N2: 3 | O2: 4 | P2: 5 | Q2: 6 | R2: 7 | S2: 8 | T2: 9 | U2: 10
A3: 2 | B3: =VLOOKUP($B$1,$I$3:$U$39,C3,0) -> 0.16 | C3: 5 | H3: 37 | I3: ชั่วระยะเวลา 10/10 | J3: 10TLA | K3: 1 | L3: 0.28 | M3: 0.16 | N3: 0.1 | O3: 0.05 | P3: 0.05 | Q3: 0.05 | R3: 0.05 | S3: 0.05 | T3: 0.05 | U3: 0.05
A4: 3 | B4: =VLOOKUP($B$1,$I$3:$U$39,C4,0) -> 0.1 | C4: 6 | H4: 36 | I4: ชั่วระยะเวลา 20/20 | J4: 20TLA | K4: 1 | L4: 0.3 | M4: 0.25 | N4: 0.15 | O4: 0.05 | P4: 0.05 | Q4: 0.05 | R4: 0.05 | S4: 0.05 | T4: 0.05 | U4: 0.05
A5: 4 | B5: =VLOOKUP($B$1,$I$3:$U$39,C5,0) -> 0.05 | C5: 7 | H5: 35 | I5: ไลฟ์ โพรเทคเตอร์ เอ็กซ์ตร้า A90/1 | J5: 1LP | K5: 1 | L5: 0.03
A6: 5 | B6: =VLOOKUP($B$1,$I$3:$U$39,C6,0) -> 0.05 | C6: 8 | H6: 34 | I6: ไลฟ์ โพรเทคเตอร์ 5 (A90/5) | J6: 5LP | K6: 1 | L6: 0.1 | M6: 0.04 | N6: 0.025
A7: 6 | B7: =VLOOKUP($B$1,$I$3:$U$39,C7,0) -> 0.05 | C7: 9 | H7: 33 | I7: ไลฟ์ โพรเทคเตอร์ 10 (A90/10) | J7: 10LP | K7: 1 | L7: 0.2 | M7: 0.08 | N7: 0.05 | O7: 0.025 | P7: 0.025 | Q7: 0.025 | R7: 0.025 | S7: 0.025 | T7: 0.025 | U7: 0.025
A8: 7 | B8: =VLOOKUP($B$1,$I$3:$U$39,C8,0) -> 0.05 | C8: 10 | H8: 32 | I8: ไลฟ์ โพรเทคเตอร์ 15 (A90/15) | J8: 15LP | K8: 1 | L8: 0.25 | M8: 0.1 | N8: 0.0625 | O8: 0.035 | P8: 0.035 | Q8: 0.035 | R8: 0.035 | S8: 0.035 | T8: 0.035 | U8: 0.035
A9: 8 | B9: =VLOOKUP($B$1,$I$3:$U$39,C9,0) -> 0.05 | C9: 11 | H9: 31 | I9: ไลฟ์ โพรเทคเตอร์ 20 (A90/20) | J9: 20LPB | K9: 0.75 | L9: 0.38 | M9: 0.155 | N9: 0.095 | O9: 0.035 | P9: 0.035 | Q9: 0.035 | R9: 0.035 | S9: 0.035 | T9: 0.035 | U9: 0.035
A10: 9 | B10: =VLOOKUP($B$1,$I$3:$U$39,C10,0) -> 0.05 | C10: 12 | H10: 30 | I10: ไลฟ์ โพรเทคเตอร์ พลัส 20 (A99/20) | J10: 20LPPA | K10: 1 | L10: 0.24 | M10: 0.1 | N10: 0.06
A11: 10 | B11: =VLOOKUP($B$1,$I$3:$U$39,C11,0) -> 0.05 | C11: 13 | H11: 29 | I11: สุพรีม ไลฟ์ โพรเทคเตอร์ A90/20 | J11: 20SLPA | K11: 0.75 | L11: 0.4 | M11: 0.16 | N11: 0.1 | O11: 0.05 | P11: 0.05 | Q11: 0.05 | R11: 0.05 | S11: 0.05 | T11: 0.05 | U11: 0.05
H12: 28 | I12: ตลอดชีพ (ไม่มีเงินปันผล) A99/A90 | J12: WH90A | K12: 1 | L12: 0.36 | M12: 0.15 | N12: 0.09 | O12: 0.01 | P12: 0.01 | Q12: 0.01 | R12: 0.01 | S12: 0.01 | T12: 0.01 | U12: 0.01
H13: 27 | I13: 12 ทีเอ็กซ์ A90/12 | J13: 12TXM | K13: 1 | L13: 0.12 | M13: 0.05 | N13: 0.03
H14: 26 | I14: 24 ทีเอ็กซ์ A90/24 | J14: 24TXN | K14: 0.75 | L14: 0.3 | M14: 0.15 | N14: 0.1 | O14: 0.05
H15: 25 | I15: ตลอดชีพ เอ็กซ์ตร้า A90/10 | J15: WXN10 | K15: 1 | L15: 0.2 | M15: 0.1 | N15: 0.05 | O15: 0.025
H16: 24 | I16: ตลอดชีพ เอ็กซ์ตร้า A90/15 | J16: WXN15 | K16: 1 | L16: 0.2 | M16: 0.1 | N16: 0.075 | O16: 0.05 | P16: 0.025
H17: 23 | I17: เกษียณเพิ่มสุข A90/15 | J17: RE15 | K17: 1 | L17: 0.2 | M17: 0.08 | N17: 0.05
H18: 22 | I18: 7 สมาร์ท แพลน (21/7) | J18: 7SM | K18: 1 | L18: 0.1 | M18: 0.04 | N18: 0.025
H19: 21 | I19: 15 สมาร์ท แพลน (21/15) | J19: 15SPN | K19: 1 | L19: 0.17 | M19: 0.0875 | N19: 0.0525 | O19: 0.035 | P19: 0.0175
H20: 20 | I20: สมาร์ท เซฟวิ่งส์ 12/4 | J20: SS12 | K20: 1 | L20: 0.06 | M20: 0.024 | N20: 0.015
H21: 19 | I21: สมาร์ท เซฟวิ่งส์ 15/8 | J21: 8SS | K21: 1 | L21: 0.08 | M21: 0.032 | N21: 0.02
H22: 18 | I22: เกษียณออมทรัพย์ A60/A55 | J22: RS60 | K22: 1 | L22: 0.28 | M22: 0.12 | N22: 0.075 | O22: 0.02 | P22: 0.02 | Q22: 0.01 | R22: 0.01 | S22: 0.01 | T22: 0.01 | U22: 0.01
H23: 17 | I23: เกษียณออมทรัพย์ A65/A60 | J23: RS65 | K23: 1 | L23: 0.28 | M23: 0.12 | N23: 0.075 | O23: 0.02 | P23: 0.02 | Q23: 0.01 | R23: 0.01 | S23: 0.01 | T23: 0.01 | U23: 0.01
H24: 16 | I24: สเตป เซฟวิ่งส์ A78/6 | J24: S678 | K24: 0.5 | L24: 0.15 | M24: 0.06 | N24: 0.0375 | O24: 0.01
H25: 15 | I25: แอนนิวตี้ เรดดี้ A90/5 | J25: AR5N | K25: 1 | L25: 0.03 | M25: 0.012 | N25: 0.0075
H26: 14 | I26: แอนนิวตี้ เรดดี้ A90/A60 | J26: AR60N | K26: 1 | L26: 0.2 | M26: 0.1 | N26: 0.05 | O26: 0.05 | P26: 0.05 | Q26: 0.025 | R26: 0.025 | S26: 0.025 | T26: 0.025 | U26: 0.025
H27: 13 | I27: แอนนิวตี้ เรดดี้ A90/A65 | J27: AR65 | K27: 1 | L27: 0.2 | M27: 0.1 | N27: 0.05 | O27: 0.05 | P27: 0.05 | Q27: 0.025 | R27: 0.025 | S27: 0.025 | T27: 0.025 | U27: 0.025
H28: 12 | I28: บำนาญเพิ่มสุข A85/15 | J28: 15HA | K28: 1 | L28: 0.12 | M28: 0.1 | N28: 0.05
H29: 11 | I29: บำนาญเพิ่มสุข A85/A55 | J29: HA55 | K29: 1 | L29: 0.2 | M29: 0.1 | N29: 0.05 | O29: 0.05 | P29: 0.05 | Q29: 0.05 | R29: 0.05 | S29: 0.05 | T29: 0.05 | U29: 0.05
H30: 10 | I30: สเตป แอนนิวตี้ A90/10 | J30: AS10 | K30: 1 | L30: 0.1 | M30: 0.04 | N30: 0.025
H31: 9 | I31: สเตป แอนนิวตี้ A90/A60 | J31: AS60 | K31: 1 | L31: 0.3 | M31: 0.12 | N31: 0.075 | O31: 0.05 | P31: 0.05 | Q31: 0.015 | R31: 0.015 | S31: 0.015 | T31: 0.015 | U31: 0.015
H32: 8 | I32: ซีไอ เอ็กซ์ตร้า พลัส A90/10 | J32: 10CX | K32: 1 | L32: 0.2 | M32: 0.1 | N32: 0.07 | O32: 0.02 | P32: 0.01 | Q32: 0.01 | R32: 0.01 | S32: 0.01 | T32: 0.01 | U32: 0.01
H33: 7 | I33: ซีไอ เอ็กซ์ตร้า พลัส A90/20 | J33: 20CX | K33: 1 | L33: 0.3 | M33: 0.16 | N33: 0.1 | O33: 0.02 | P33: 0.01 | Q33: 0.01 | R33: 0.01 | S33: 0.01 | T33: 0.01 | U33: 0.01
H34: 6 | I34: ซิกเนเจอร์ เลกาซี 5 (A99/5) | J34: 5SLC | K34: 1 | L34: 0.15 | M34: 0.06 | N34: 0.0375 | O34: 0.01 | P34: 0.01
H35: 5 | I35: ซิกเนเจอร์ เลกาซี 10 (A99/10) | J35: 10SLB | K35: 1 | L35: 0.3 | M35: 0.12 | N35: 0.08 | O35: 0.025 | P35: 0.025 | Q35: 0.025 | R35: 0.025 | S35: 0.025 | T35: 0.025 | U35: 0.025
H36: 4 | I36: โปร เซฟเวอร์ 20/10 | J36: 10ES | K36: 1 | L36: 0.1 | M36: 0.05 | N36: 0.03
H37: 3 | I37: สตาร์ต เซฟเวอร์ 25/15 | J37: 15ES | K37: 1 | L37: 0.23 | M37: 0.1 | N37: 0.0625 | O37: 0.01 | P37: 0.01
H38: 2 | I38: 868 อีลีท เซฟวิ่งส์ A68/8 | J38: S868 | K38: 1 | L38: 0.15 | M38: 0.06 | N38: 0.0375 | O38: 0.01
H39: 1 | I39: 818 อีลีท เซฟวิ่งส์ 18/8 | J39: S818 | K39: 1 | L39: 0.05 | M39: 0.02 | N39: 0.0125 | O39: 0.01
H40: 0

Sheet โครงสร้างตัวแทน
B3: โครงสร้างผลประโยชน์ตัวแทน
B4: 1. ผลประโยชน์ตัวแทน (FYC,RYC) | C4: คอมมิชชั่นสูงสุด 40%
B5: 2. โบนัสรายเดือน (Momthly Bonus : MB) | C5: MB = FYC x อัตราโบนัส
B6: จ่ายตามตารางการจ่ายเงินของบริษัทฯ เดือนละครั้ง | C6: ยอดสะสม FYC (บาท) แต่ละเดือน | E6: มี K2 (ผลงานส่วนตัว) มีค่าไม่น้อยกว่า 70%
C7: 8,000 - 16,000 | E7: 0.2
C8: 16,001 - 32,000 | E8: 0.25
C9: 32,001 - 64,000 | E9: 0.3
C10: 64,001 เป็นต้นไป | E10: 0.35
B11: 3. โบนัสครึ่งปี ( MYB ) | C11: MYB = FYC x อัตราโบนัส
B12: 1.) โบนัสครึ่งปี ( ม.ค.-มิ.ย. / ก.ค. - ธ.ค. ) 2.) วัดผลเพื่อจ่ายโบนัสครึ่งปีล่วงหน้า ให้ ณ สิ้นไตรมาสที่ 1 และไตรมาสที่ 3 3.) มีการปรับปรุงเพื่อจ่ายเพิ่มหรือเรียกคืน เมื่อครบทุกครึ่งปีปฏิทิน | C12: ยอดสะสม FYC (บาท) แต่ละครึ่งปีปฏิทิน | E12: มี K2 (ผลงานส่วนตัว) มีค่าไม่น้อยกว่า 70%
C13: 40,000 - 60,000 | E13: 0.175
C14: 60,001 - 100,000 | E14: 0.2
C15: 100,001 - 150,000 | E15: 0.225
C16: 150,001 - 200,000 | E16: 0.25
C17: 200,001 - 250,000 | E17: 0.275
C18: 250,001 - 300,000 | E18: 0.3
C19: 300,001 - 400,000 | E19: 0.325
C20: 400,001 เป็นต้นไป | E20: 0.35
C21: ถ้า K2 >= 85% คิดเพิ่มเป็น 110% ของตารางข้างบน (จาก 35% เป็น 38.5% ของ FYC)
B22: 4. ผลประโยชน์จากอาชีพ (CB) | C22: CB = RYC (ปีที่ 2 -10) x %K2 หารด้วย 12 | E22: CB = RYC (ปีที่ 2 -10) x %K2 x 110% หารด้วย 12
B23: เฉลี่ยจ่ายเป็นรายเดือน | C23: 1.) FYC ปีที่ผ่านมา ไม่ต่ำกว่า 100,000 บาท | E23: 1.) FYC ปีที่ผ่านมา ไม่ต่ำกว่า 200,000 บาท
C24: 2.) Active Month ไม่ต่ำกว่า 8 เดือน | E24: 2.) Active Month ไม่ต่ำกว่า 8 เดือน
C25: 3.) ผลงานส่วนตัว 8 ราย | E25: 3.) ผลงานส่วนตัว 8 ราย
C26: 4.) K2 >= 75% วัดผลสิ้น ก.พ. ปีถัดไป | E26: 4.) K2 >= 85% วัดผลสิ้น ก.พ. ปีถัดไป
B27: 5. โบนัสตัวแทนใหม่ (NAB)
B28: นับรายสามัญเท่านั้น | C28: 1.) นับผลงานอนุมัติและคำนวณจ่าย 6 เดือนแรก (นับเดือนแต่งตั้งเป็นเดือนที่ 1)
C29: 2.) เฉพาะ 3 เดือนแรก จ่าย ณ สิ้นเดือนที่ 3
C30: FYC >= 20,000 และ มีงานอนุมัติสะสม 3 ราย | E30: 6000
C31: FYC >= 50,000 และ มีงานอนุมัติสะสม 5 ราย | E31: 15000
C32: 3.) เดือนที่ 4 - เดือนที่ 6
C33: FYC >= 40,000 และ มีงานอนุมัติสะสม 5 ราย | E33: 10000
C34: FYC >= 100,000 และ มีงานอนุมัติสะสม 10 ราย | E34: 25000
B35: 6. ประกันชีวิตและประกันสุขภาพ
B36: ยอดสะสม FYC (บาท) | C36: รายละเอียด | E36: รายละเอียดผลประโยชน์ (ปีถัดไป)
B37: 100000 | C37: 1.) มี K2 >= 70% | E37: ประกันชีวิตทุน 100,000 บาท
C38: 2.) ผลงานส่วนตัว 8 ราย ( ม.ค. - ธ.ค. )
C39: 3.) มีทุนประกันชีวิตส่วนตัวที่บริษัทไม่น้อยกว่า 100,000 บาท
B40: 300000 | C40: 1.) มี K2 >= 70% | E40: ประกันชีวิตทุน 300,000 บาท
C41: 2.) ผลงานส่วนตัว 8 ราย ( ม.ค. - ธ.ค. ) | E41: GHS 800 บาท
C42: 3.) มีทุนประกันชีวิตส่วนตัวที่บริษัทไม่น้อยกว่า 300,000 บาท | E42: OPD 500 บาท
...

Sheet โครงสร้างรายได้
B1: =M3 -> สุพรีม ไลฟ์ โพรเทคเตอร์ A90/20 | I1: นับผลงาน | L1: พ.ศ. | M1: 2569
B2: ผลประโยชน์ตัวแทน | I2: =M4 -> 0.75
A3: FYP (ปี) | B3: 3000000 | G3: บาท | H3: K2 | I3: 0.75 | L3: แบบประกัน(Com.) | M3: =COM!$B$1 -> สุพรีม ไลฟ์ โพรเทคเตอร์ A90/20 | O3: =COM!E1 -> 20SLPA
A4: ตัวแทน (AG) | B4: อัตรา | C4: =M1 -> 2569 | D4: =C4+1 -> 2570 | E4: =D4+1 -> 2571 | F4: =E4+1 -> 2572 | G4: =F4+1 -> 2573 | H4: =G4+1 -> 2574 | I4: รวม | L4: นับผลงาน | M4: =COM!F1 -> 0.75
A5: FYC (Commission) | B5: =IF($N$5="Auto",COM!$B2,IF($N$5="Manual",M5,0)) -> 0.4 | C5: =$B$3*B5 -> 1200000 | I5: =SUM(C5:H5) -> 1200000 | L5: 1st | M5: 0.18 | N5: Auto
A6: RYC1 | B6: =IF($N$5="Auto",COM!$B3,IF($N$5="Manual",M6,0)) -> 0.16 | D6: =$B$3*B6 -> 480000 | I6: =SUM(C6:H6) -> 480000 | L6: 2nd | M6: 0.08
A7: RYC2 | B7: =IF($N$5="Auto",COM!$B4,IF($N$5="Manual",M7,0)) -> 0.1 | E7: =$B$3*B7 -> 300000 | I7: =SUM(C7:H7) -> 300000 | L7: 3rd | M7: 0.05
A8: RYC3 | B8: =IF($N$5="Auto",COM!$B5,IF($N$5="Manual",M8,0)) -> 0.05 | F8: =$B$3*B8 -> 150000 | I8: =SUM(C8:H8) -> 150000 | L8: 4th | M8: 0.025
A9: RYC4 | B9: =IF($N$5="Auto",COM!$B6,IF($N$5="Manual",M9,0)) -> 0.05 | G9: =$B$3*B9 -> 150000 | I9: =SUM(C9:H9) -> 150000 | L9: 5th | M9: 0.025
A10: โบนัสรายเดือน (MB) | B10: =IF($I$3<70%,0, IF($C$5/12>64000,"35%", IF(AND($C$5/12>32000,$C$5/12<=64000),"30%", IF(AND($C$5/12>16000,$C$5/12<=32000),"25%", IF(AND($C$5/12>8000,$C$5/12<=16000),"20%", 0))))) -> 35% | C10: =B10*$M$4*C5 -> 315000 | I10: =SUM(C10:H10) -> 315000
A11: โบนัสครึ่งปี (MYB) | B11: =IF($C$5/2>400000,"35%", IF(AND($C$5/2>300000,$C$5/2<=400000),"32.5%", IF(AND($C$5/2>250000,$C$5/2<=300000),"30%", IF(AND($C$5/2>200000,$C$5/2<=250000),"27.5%", IF(AND($C$5/2>150000,$C$5/2<=200000),"25%", IF(AND($C$5/2>100000,$C$5/2<=150000),"22.5%", IF(AND($C$5/2>60000,$C$5/2<=100000),"20%", IF(AND($C$5/2>40000,$C$5/2<=60000),"17.5%", 1))))))))*(IF($I$3<70%,0%,IF(AND($I$3>=70%,$I$3<85%),100%,IF($I$3>=85%,110%,)))) -> 0.35 | C11: =C5*$M$4*B11 -> 315000 | I11: =SUM(C11:H11) -> 315000
A12: ผลประโยชน์จากอาชีพ (CB) | E12: =IF(AND($C$5*$M$4>=200000,$I$3>=85%),SUM(D6:D9)*$I$3*$I$2*110%,IF(AND($C$5*$M$4>=100000,$I$3>=75%),SUM(D6:D9)*$I$3*$I$2*100%,0)) -> 270000 | F12: =IF(AND($C$5*$M$4>=200000,$I$3>=85%),SUM(E6:E9)*$I$3*$I$2*110%,IF(AND($C$5*$M$4>=100000,$I$3>=75%),SUM(E6:E9)*$I$3*$I$2*100%,0)) -> 168750 | G12: =IF(AND($C$5*$M$4>=200000,$I$3>=85%),SUM(F6:F9)*$I$3*$I$2*110%,IF(AND($C$5*$M$4>=100000,$I$3>=75%),SUM(F6:F9)*$I$3*$I$2*100%,0)) -> 84375 | H12: =IF(AND($C$5*$M$4>=200000,$I$3>=85%),SUM(G6:G9)*$I$3*$I$2*110%,IF(AND($C$5*$M$4>=100000,$I$3>=75%),SUM(G6:G9)*$I$3*$I$2*100%,0)) -> 84375 | I12: =SUM(C12:H12) -> 607500
A13: โบนัสตัวแทนใหม่ (NAB) | B13: =M13*3&" ราย/3ด." -> 15 ราย/3ด. | C13: =IF(AND(M13*3>=5,$C$5*$M$4/4>=50000),15000,IF(AND(M13*3>=3,$C$5*$M$4/4>=20000),6000,0))+IF(AND(M13*3>=10,$C$5*$M$4/4>=100000),25000,IF(AND(M13*3>=5,$C$5*$M$4/4>=40000),10000,0)) -> 40000 | I13: =SUM(C13:H13) -> 40000 | L13: จำนวนราย/เดือน | M13: 5
A14: กองทุนเงินสะสม (SP) | B14: 0.05 | C14: =$C$5*$M$4*$B$14 -> 45000 | I14: =SUM(C14:H14) -> 45000
A15: รวม | C15: =SUM(C5:C14) -> 1915000 | D15: =SUM(D5:D14) -> 480000 | E15: =SUM(E5:E14) -> 570000 | F15: =SUM(F5:F14) -> 318750 | G15: =SUM(G5:G14) -> 234375 | H15: =SUM(H5:H14) -> 84375 | I15: =SUM(C15:H15) -> 3602500

Sheet รายได้
B2: ตารางคำนวณรายได้ | AA2: เงินสมทบรายเดือน | AF2: แผน 1 | AP2: แผน 2 | AZ2: แผน 3
AA3: บริษัทจ่าย | AB3: 5000 | AC3: 10000 | AD3: 20000 | AF3: ตารางการจ่ายผลประโยชน์ Monthly Allowance | AP3: ตารางการจ่ายผลประโยชน์ Monthly Allowance | AZ3: ตารางการจ่ายผลประโยชน์ Monthly Allowance
B4: ผลประโยชน์ตัวแทน | O4: นับผลงาน | P4: 0.75 | Q4: 0.75 | R4: 1 | AA4: อายุงาน | AB4: ต่ำกว่า Tier | AC4: Tier 1 | AD4: Tier 2 | AF4: FP | AG4: FYC อนุมัติใหม่ | AH4: Rolling FYC | AI4: รวม FYC | AJ4: Tier | AK4: Monthly Allowance | AL4: หมายเหตุ | AP4: FP | AQ4: FYC อนุมัติใหม่ | AR4: Rolling FYC | AS4: รวม FYC | AT4: Tier | AU4: Monthly Allowance | AV4: หมายเหตุ | AZ4: FP | BA4: FYC อนุมัติใหม่ | BB4: Rolling FYC | BC4: รวม FYC | BD4: Tier | BE4: Monthly Allowance | BF4: หมายเหตุ
B5: FYP | C5: =P5 -> 3000000 | D5: บาท/ปี | E5: ALL YC | G5: =SUM(H6:H10) -> 2280000 | I5: =SUM(J6:J10) -> 2100000 | K5: =SUM(L6:L10) -> 1650000 | O5: FYP | P5: 3000000 | AA5: เดือน 0 | AB5: 3000 | AF5: อายุงาน | AG5: อย่างน้อย 50% | AH5: จากเดือนก่อน | AI5: ในเดือน | AP5: อายุงาน | AQ5: อย่างน้อย 50% | AR5: จากเดือนก่อน | AS5: ในเดือน | AZ5: อายุงาน | BA5: อย่างน้อย 50% | BB5: จากเดือนก่อน | BC5: ในเดือน
B6: 1 | C6: FYC (Commission) | G6: =P6 -> 0.4 | H6: =$C$5*G6 -> 1200000 | I6: =Q6 -> 0.38 | J6: =$C$5*I6 -> 1140000 | K6: =R6 -> 0.3 | L6: =$C$5*K6 -> 900000 | O6: FYC1 | P6: 0.4 | Q6: 0.38 | R6: 0.3 | AA6: เดือน 1 | AB6: 2250 | AC6: 4500 | AD6: 10000 | AF6: เดือนที่ 1 | AG6: =$H$6 -> 1200000 | AH6: 0 | AI6: =AG6+AH6 -> 1200000 | AJ6: =IF(AND(AG6>=$AD6*50%,AI6>=$AD6),"Tier 2",IF(AND(AG6>=$AC6*50%,AI6>=$AC6),"Tier 1",0)) -> Tier 2 | AK6: =IF(AJ6="Tier 2",20000,IF(AJ6="Tier 1",10000,IF(AND(OR(AF6="เดือนที่ 1",AF6="เดือนที่ 2"),AJ6=0,AG6>=$AB6),5000,0))) -> 20000 | AL6: ="ผลงานอนุมัติใหม่"&IF(OR(AND(AJ6="Tier 1",AG6>=$AC6),AND(AJ6="Tier 2",AG6>=$AD6)),"ถึง 100%",IF(OR(AND(AJ6=0,AG6>=$AC6*50%),AND(AJ6="Tier 1",AG6>=$AC6*50%),AND(AJ6="Tier 2",AG6>=$AD6*50%)),"ถึง 50%","ไม่ถึง 50%"))&IF(AND(AJ6=0,OR(AF6="เดือนที่ 1",AF6="เดือนที่ 2"),AI6>=$AC6*50%)," และ FYC รวมถึง "&TEXT(AI6,"#,###")&" เข้ากฎเกณฑ์ข้อ 4",IF(AND(AK6=0,AI6>=$AC6,AI6<$AD6)," แม้ว่า FYC รวมจะถึง "&TEXT($AC6,"#,###")&" บาท ของ Tier 1",IF(AND(AK6=0,AI6>=$AC6,AI6>=$AD6)," แม้ว่า FYC รวมจะถึง "&TEXT($AD6,"#,###")&" บาท ของ Tier 2",IF(AND(AJ6="Tier 1",AI6>=$AC6,AI6<$AD6)," ของ Tier 1 และ FYC รวมถึง "&TEXT($AC6,"#,###")&" บาท ของ Tier 1",IF(AND(AJ6="Tier 1",AI6>=$AC6,AI6>=$AD6)," ของ Tier 1 แม้ว่า FYC รวมจะมากกว่า "&TEXT($AD6,"#,###")&" บาท ของ Tier 2",IF(AND(AJ6="Tier 2",AI6>=$AC6,AI6>=$AD6)," ของ Tier 2 และ FYC รวมถึง "&TEXT($AD6,"#,###")&" บาท ของ Tier 2","")))))) -> ผลงานอนุมัติใหม่ถึง 100% ของ Tier 2 และ FYC รวมถึง 10,000 บาท ของ Tier 2 | AM6: 1 | AN6: =IF(AM6<=$P$4,SUM($AK$6:AK6),0) -> 0 | AP6: เดือนที่ 1 | AQ6: =$J$6 -> 1140000 | AR6: 0 | AS6: =AQ6+AR6 -> 1140000 | AT6: =IF(AND(AQ6>=$AD6*50%,AS6>=$AD6),"Tier 2",IF(AND(AQ6>=$AC6*50%,AS6>=$AC6),"Tier 1",0)) -> Tier 2 | AU6: =IF(AT6="Tier 2",20000,IF(AT6="Tier 1",10000,IF(AND(OR(AP6="เดือนที่ 1",AP6="เดือนที่ 2"),AT6=0,AQ6>=$AB6),5000,0))) -> 20000 | AV6: ="ผลงานอนุมัติใหม่"&IF(OR(AND(AT6="Tier 1",AQ6>=$AC6),AND(AT6="Tier 2",AQ6>=$AD6)),"ถึง 100%",IF(OR(AND(AT6=0,AQ6>=$AC6*50%),AND(AT6="Tier 1",AQ6>=$AC6*50%),AND(AT6="Tier 2",AQ6>=$AD6*50%)),"ถึง 50%","ไม่ถึง 50%"))&IF(AND(AT6=0,OR(AP6="เดือนที่ 1",AP6="เดือนที่ 2"),AS6>=$AC6*50%)," และ FYC รวมถึง "&TEXT(AS6,"#,###")&" เข้ากฎเกณฑ์ข้อ 4",IF(AND(AU6=0,AS6>=$AC6,AS6<$AD6)," แม้ว่า FYC รวมจะถึง "&TEXT($AC6,"#,###")&" บาท ของ Tier 1",IF(AND(AU6=0,AS6>=$AC6,AS6>=$AD6)," แม้ว่า FYC รวมจะถึง "&TEXT($AD6,"#,###")&" บาท ของ Tier 2",IF(AND(AT6="Tier 1",AS6>=$AC6,AS6<$AD6)," ของ Tier 1 และ FYC รวมถึง "&TEXT($AC6,"#,###")&" บาท ของ Tier 1",IF(AND(AT6="Tier 1",AS6>=$AC6,AS6>=$AD6)," ของ Tier 1 แม้ว่า FYC รวมจะมากกว่า "&TEXT($AD6,"#,###")&" บาท ของ Tier 2",IF(AND(AT6="Tier 2",AS6>=$AC6,AS6>=$AD6)," ของ Tier 2 และ FYC รวมถึง "&TEXT($AD6,"#,###")&" บาท ของ Tier 2","")))))) -> ผลงานอนุมัติใหม่ถึง 100% ของ Tier 2 และ FYC รวมถึง 10,000 บาท ของ Tier 2 | AW6: 1 | AX6: =IF(AW6<=$P$4,SUM($AU$6:AU6),0) -> 0 | AZ6: เดือนที่ 1 | BA6: =$L$6 -> 900000 | BB6: 0 | BC6: =BA6+BB6 -> 900000 | BD6: =IF(AND(BA6>=$AD6*50%,BC6>=$AD6),"Tier 2",IF(AND(BA6>=$AC6*50%,BC6>=$AC6),"Tier 1",0)) -> Tier 2 | BE6: =IF(BD6="Tier 2",20000,IF(BD6="Tier 1",10000,IF(AND(OR(AZ6="เดือนที่ 1",AZ6="เดือนที่ 2"),BD6=0,BA6>=$AB6),5000,0))) -> 20000 | BF6: ="ผลงานอนุมัติใหม่"&IF(OR(AND(BD6="Tier 1",BA6>=$AC6),AND(BD6="Tier 2",BA6>=$AD6)),"ถึง 100%",IF(OR(AND(BD6=0,BA6>=$AC6*50%),AND(BD6="Tier 1",BA6>=$AC6*50%),AND(BD6="Tier 2",BA6>=$AD6*50%)),"ถึง 50%","ไม่ถึง 50%"))&IF(AND(BD6=0,OR(AZ6="เดือนที่ 1",AZ6="เดือนที่ 2"),BC6>=$AC6*50%)," และ FYC รวมถึง "&TEXT(BC6,"#,###")&" เข้ากฎเกณฑ์ข้อ 4",IF(AND(BE6=0,BC6>=$AC6,BC6<$AD6)," แม้ว่า FYC รวมจะถึง "&TEXT($AC6,"#,###")&" บาท ของ Tier 1",IF(AND(BE6=0,BC6>=$AC6,BC6>=$AD6)," แม้ว่า FYC รวมจะถึง "&TEXT($AD6,"#,###")&" บาท ของ Tier 2",IF(AND(BD6="Tier 1",BC6>=$AC6,BC6<$AD6)," ของ Tier 1 และ FYC รวมถึง "&TEXT($AC6,"#,###")&" บาท ของ Tier 1",IF(AND(BD6="Tier 1",BC6>=$AC6,BC6>=$AD6)," ของ Tier 1 แม้ว่า FYC รวมจะมากกว่า "&TEXT($AD6,"#,###")&" บาท ของ Tier 2",IF(AND(BD6="Tier 2",BC6>=$AC6,BC6>=$AD6)," ของ Tier 2 และ FYC รวมถึง "&TEXT($AD6,"#,###")&" บาท ของ Tier 2","")))))) -> ผลงานอนุมัติใหม่ถึง 100% ของ Tier 2 และ FYC รวมถึง 10,000 บาท ของ Tier 2 | BG6: 1 | BH6: =IF(BG6<=$P$4,SUM($BE$6:BE6),0) -> 0
C7: RYC1 | G7: =P7 -> 0.16 | H7: =$C$5*G7 -> 480000 | I7: =Q7 -> 0.155 | J7: =$C$5*I7 -> 465000 | K7: =R7 -> 0.12 | L7: =$C$5*K7 -> 360000 | O7: RYC2 | P7: 0.16 | Q7: 0.155 | R7: 0.12 | AA7: เดือน 2 | AB7: 3000 | AC7: 6000 | AD7: 12000 | AF7: เดือนที่ 2 | AG7: =$H$6 -> 1200000 | AH7: 0 | AI7: =AG7+AH7 -> 1200000 | AJ7: =IF(AND(AG7>=$AD7*50%,AI7>=$AD7),"Tier 2",IF(AND(AG7>=$AC7*50%,AI7>=$AC7),"Tier 1",0)) -> Tier 2 | AK7: =IF(AJ7="Tier 2",20000,IF(AJ7="Tier 1",10000,IF(AND(OR(AF7="เดือนที่ 1",AF7="เดือนที่ 2"),AJ7=0,AG7>=$AB7),5000,0))) -> 20000 | AL7: ="ผลงานอนุมัติใหม่"&IF(OR(AND(AJ7="Tier 1",AG7>=$AC7),AND(AJ7="Tier 2",AG7>=$AD7)),"ถึง 100%",IF(OR(AND(AJ7=0,AG7>=$AC7*50%),AND(AJ7="Tier 1",AG7>=$AC7*50%),AND(AJ7="Tier 2",AG7>=$AD7*50%)),"ถึง 50%","ไม่ถึง 50%"))&IF(AND(AJ7=0,OR(AF7="เดือนที่ 1",AF7="เดือนที่ 2"),AI7>=$AC7*50%)," และ FYC รวมถึง "&TEXT(AI7,"#,###")&" เข้ากฎเกณฑ์ข้อ 4",IF(AND(AK7=0,AI7>=$AC7,AI7<$AD7)," แม้ว่า FYC รวมจะถึง "&TEXT($AC7,"#,###")&" บาท ของ Tier 1",IF(AND(AK7=0,AI7>=$AC7,AI7>=$AD7)," แม้ว่า FYC รวมจะถึง "&TEXT($AD7,"#,###")&" บาท ของ Tier 2",IF(AND(AJ7="Tier 1",AI7>=$AC7,AI7<$AD7)," ของ Tier 1 และ FYC รวมถึง "&TEXT($AC7,"#,###")&" บาท ของ Tier 1",IF(AND(AJ7="Tier 1",AI7>=$AC7,AI7>=$AD7)," ของ Tier 1 แม้ว่า FYC รวมจะมากกว่า "&TEXT($AD7,"#,###")&" บาท ของ Tier 2",IF(AND(AJ7="Tier 2",AI7>=$AC7,AI7>=$AD7)," ของ Tier 2 และ FYC รวมถึง "&TEXT($AD7,"#,###")&" บาท ของ Tier 2","")))))) -> ผลงานอนุมัติใหม่ถึง 100% ของ Tier 2 และ FYC รวมถึง 12,000 บาท ของ Tier 2 | AM7: 2 | AN7: =IF(AM7<=$P$4,SUM($AK$6:AK7),0) -> 0 | AP7: เดือนที่ 2 | AQ7: =$J$6 -> 1140000 | AR7: 0 | AS7: =AQ7+AR7 -> 1140000 | AT7: =IF(AND(AQ7>=$AD7*50%,AS7>=$AD7),"Tier 2",IF(AND(AQ7>=$AC7*50%,AS7>=$AC7),"Tier 1",0)) -> Tier 2 | AU7: =IF(AT7="Tier 2",20000,IF(AT7="Tier 1",10000,IF(AND(OR(AP7="เดือนที่ 1",AP7="เดือนที่ 2"),AT7=0,AQ7>=$AB7),5000,0))) -> 20000 | AV7: ="ผลงานอนุมัติใหม่"&IF(OR(AND(AT7="Tier 1",AQ7>=$AC7),AND(AT7="Tier 2",AQ7>=$AD7)),"ถึง 100%",IF(OR(AND(AT7=0,AQ7>=$AC7*50%),AND(AT7="Tier 1",AQ7>=$AC7*50%),AND(AT7="Tier 2",AQ7>=$AD7*50%)),"ถึง 50%","ไม่ถึง 50%"))&IF(AND(AT7=0,OR(AP7="เดือนที่ 1",AP7="เดือนที่ 2"),AS7>=$AC7*50%)," และ FYC รวมถึง "&TEXT(AS7,"#,###")&" เข้ากฎเกณฑ์ข้อ 4",IF(AND(AU7=0,AS7>=$AC7,AS7<$AD7)," แม้ว่า FYC รวมจะถึง "&TEXT($AC7,"#,###")&" บาท ของ Tier 1",IF(AND(AU7=0,AS7>=$AC7,AS7>=$AD7)," แม้ว่า FYC รวมจะถึง "&TEXT($AD7,"#,###")&" บาท ของ Tier 2",IF(AND(AT7="Tier 1",AS7>=$AC7,AS7<$AD7)," ของ Tier 1 และ FYC รวมถึง "&TEXT($AC7,"#,###")&" บาท ของ Tier 1",IF(AND(AT7="Tier 1",AS7>=$AC7,AS7>=$AD7)," ของ Tier 1 แม้ว่า FYC รวมจะมากกว่า "&TEXT($AD7,"#,###")&" บาท ของ Tier 2",IF(AND(AT7="Tier 2",AS7>=$AC7,AS7>=$AD7)," ของ Tier 2 และ FYC รวมถึง "&TEXT($AD7,"#,###")&" บาท ของ Tier 2","")))))) -> ผลงานอนุมัติใหม่ถึง 100% ของ Tier 2 และ FYC รวมถึง 12,000 บาท ของ Tier 2 | AW7: 2 | AX7: =IF(AW7<=$P$4,SUM($AU$6:AU7),0) -> 0 | AZ7: เดือนที่ 2 | BA7: =$L$6 -> 900000 | BB7: 0 | BC7: =BA7+BB7 -> 900000 | BD7: =IF(AND(BA7>=$AD7*50%,BC7>=$AD7),"Tier 2",IF(AND(BA7>=$AC7*50%,BC7>=$AC7),"Tier 1",0)) -> Tier 2 | BE7: =IF(BD7="Tier 2",20000,IF(BD7="Tier 1",10000,IF(AND(OR(AZ7="เดือนที่ 1",AZ7="เดือนที่ 2"),BD7=0,BA7>=$AB7),5000,0))) -> 20000 | BF7: ="ผลงานอนุมัติใหม่"&IF(OR(AND(BD7="Tier 1",BA7>=$AC7),AND(BD7="Tier 2",BA7>=$AD7)),"ถึง 100%",IF(OR(AND(BD7=0,BA7>=$AC7*50%),AND(BD7="Tier 1",BA7>=$AC7*50%),AND(BD7="Tier 2",BA7>=$AD7*50%)),"ถึง 50%","ไม่ถึง 50%"))&IF(AND(BD7=0,OR(AZ7="เดือนที่ 1",AZ7="เดือนที่ 2"),BC7>=$AC7*50%)," และ FYC รวมถึง "&TEXT(BC7,"#,###")&" เข้ากฎเกณฑ์ข้อ 4",IF(AND(BE7=0,BC7>=$AC7,BC7<$AD7)," แม้ว่า FYC รวมจะถึง "&TEXT($AC7,"#,###")&" บาท ของ Tier 1",IF(AND(BE7=0,BC7>=$AC7,BC7>=$AD7)," แม้ว่า FYC รวมจะถึง "&TEXT($AD7,"#,###")&" บาท ของ Tier 2",IF(AND(BD7="Tier 1",BC7>=$AC7,BC7<$AD7)," ของ Tier 1 และ FYC รวมถึง "&TEXT($AC7,"#,###")&" บาท ของ Tier 1",IF(AND(BD7="Tier 1",BC7>=$AC7,BC7>=$AD7)," ของ Tier 1 แม้ว่า FYC รวมจะมากกว่า "&TEXT($AD7,"#,###")&" บาท ของ Tier 2",IF(AND(BD7="Tier 2",BC7>=$AC7,BC7>=$AD7)," ของ Tier 2 และ FYC รวมถึง "&TEXT($AD7,"#,###")&" บาท ของ Tier 2","")))))) -> ผลงานอนุมัติใหม่ถึง 100% ของ Tier 2 และ FYC รวมถึง 12,000 บาท ของ Tier 2 | BG7: 2 | BH7: =IF(BG7<=$P$4,SUM($BE$6:BE7),0) -> 0
C8: RYC2 | G8: =P8 -> 0.1 | H8: =$C$5*G8 -> 300000 | I8: =Q8 -> 0.095 | J8: =$C$5*I8 -> 285000 | K8: =R8 -> 0.08 | L8: =$C$5*K8 -> 240000 | O8: RYC3 | P8: 0.1 | Q8: 0.095 | R8: 0.08 | AA8: เดือน 3 | AC8: 10000 | AD8: 18000 | AF8: เดือนที่ 3 | AG8: =$H$6 -> 1200000 | AH8: 0 | AI8: =AG8+AH8 -> 1200000 | AJ8: =IF(AND(AG8>=$AD8*50%,AI8>=$AD8),"Tier 2",IF(AND(AG8>=$AC8*50%,AI8>=$AC8),"Tier 1",0)) -> Tier 2 | AK8: =IF(AJ8="Tier 2",20000,IF(AJ8="Tier 1",10000,IF(AND(OR(AF8="เดือนที่ 1",AF8="เดือนที่ 2"),AJ8=0,AG8>=$AB8),5000,0))) -> 20000 | AL8: ="ผลงานอนุมัติใหม่"&IF(OR(AND(AJ8="Tier 1",AG8>=$AC8),AND(AJ8="Tier 2",AG8>=$AD8)),"ถึง 100%",IF(OR(AND(AJ8=0,AG8>=$AC8*50%),AND(AJ8="Tier 1",AG8>=$AC8*50%),AND(AJ8="Tier 2",AG8>=$AD8*50%)),"ถึง 50%","ไม่ถึง 50%"))&IF(AND(AJ8=0,OR(AF8="เดือนที่ 1",AF8="เดือนที่ 2"),AI8>=$AC8*50%)," และ FYC รวมถึง "&TEXT(AI8,"#,###")&" เข้ากฎเกณฑ์ข้อ 4",IF(AND(AK8=0,AI8>=$AC8,AI8<$AD8)," แม้ว่า FYC รวมจะถึง "&TEXT($AC8,"#,###")&" บาท ของ Tier 1",IF(AND(AK8=0,AI8>=$AC8,AI8>=$AD8)," แม้ว่า FYC รวมจะถึง "&TEXT($AD8,"#,###")&" บาท ของ Tier 2",IF(AND(AJ8="Tier 1",AI8>=$AC8,AI8<$AD8)," ของ Tier 1 และ FYC รวมถึง "&TEXT($AC8,"#,###")&" บาท ของ Tier 1",IF(AND(AJ8="Tier 1",AI8>=$AC8,AI8>=$AD8)," ของ Tier 1 แม้ว่า FYC รวมจะมากกว่า "&TEXT($AD8,"#,###")&" บาท ของ Tier 2",IF(AND(AJ8="Tier 2",AI8>=$AC8,AI8>=$AD8)," ของ Tier 2 และ FYC รวมถึง "&TEXT($AD8,"#,###")&" บาท ของ Tier 2","")))))) -> ผลงานอนุมัติใหม่ถึง 100% ของ Tier 2 และ FYC รวมถึง 18,000 บาท ของ Tier 2 | AM8: 3 | AN8: =IF(AM8<=$P$4,SUM($AK$6:AK8),0) -> 0 | AP8: เดือนที่ 3 | AQ8: =$J$6 -> 1140000 | AR8: 0 | AS8: =AQ8+AR8 -> 1140000 | AT8: =IF(AND(AQ8>=$AD8*50%,AS8>=$AD8),"Tier 2",IF(AND(AQ8>=$AC8*50%,AS8>=$AC8),"Tier 1",0)) -> Tier 2 | AU8: =IF(AT8="Tier 2",20000,IF(AT8="Tier 1",10000,IF(AND(OR(AP8="เดือนที่ 1",AP8="เดือนที่ 2"),AT8=0,AQ8>=$AB8),5000,0))) -> 20000 | AV8: ="ผลงานอนุมัติใหม่"&IF(OR(AND(AT8="Tier 1",AQ8>=$AC8),AND(AT8="Tier 2",AQ8>=$AD8)),"ถึง 100%",IF(OR(AND(AT8=0,AQ8>=$AC8*50%),AND(AT8="Tier 1",AQ8>=$AC8*50%),AND(AT8="Tier 2",AQ8>=$AD8*50%)),"ถึง 50%","ไม่ถึง 50%"))&IF(AND(AT8=0,OR(AP8="เดือนที่ 1",AP8="เดือนที่ 2"),AS8>=$AC8*50%)," และ FYC รวมถึง "&TEXT(AS8,"#,###")&" เข้ากฎเกณฑ์ข้อ 4",IF(AND(AU8=0,AS8>=$AC8,AS8<$AD8)," แม้ว่า FYC รวมจะถึง "&TEXT($AC8,"#,###")&" บาท ของ Tier 1",IF(AND(AU8=0,AS8>=$AC8,AS8>=$AD8)," แม้ว่า FYC รวมจะถึง "&TEXT($AD8,"#,###")&" บาท ของ Tier 2",IF(AND(AT8="Tier 1",AS8>=$AC8,AS8<$AD8)," ของ Tier 1 และ FYC รวมถึง "&TEXT($AC8,"#,###")&" บาท ของ Tier 1",IF(AND(AT8="Tier 1",AS8>=$AC8,AS8>=$AD8)," ของ Tier 1 แม้ว่า FYC รวมจะมากกว่า "&TEXT($AD8,"#,###")&" บาท ของ Tier 2",IF(AND(AT8="Tier 2",AS8>=$AC8,AS8>=$AD8)," ของ Tier 2 และ FYC รวมถึง "&TEXT($AD8,"#,###")&" บาท ของ Tier 2","")))))) -> ผลงานอนุมัติใหม่ถึง 100% ของ Tier 2 และ FYC รวมถึง 18,000 บาท ของ Tier 2 | AW8: 3 | AX8: =IF(AW8<=$P$4,SUM($AU$6:AU8),0) -> 0 | AZ8: เดือนที่ 3 | BA8: =$L$6 -> 900000 | BB8: 0 | BC8: =BA8+BB8 -> 900000 | BD8: =IF(AND(BA8>=$AD8*50%,BC8>=$AD8),"Tier 2",IF(AND(BA8>=$AC8*50%,BC8>=$AC8),"Tier 1",0)) -> Tier 2 | BE8: =IF(BD8="Tier 2",20000,IF(BD8="Tier 1",10000,IF(AND(OR(AZ8="เดือนที่ 1",AZ8="เดือนที่ 2"),BD8=0,BA8>=$AB8),5000,0))) -> 20000 | BF8: ="ผลงานอนุมัติใหม่"&IF(OR(AND(BD8="Tier 1",BA8>=$AC8),AND(BD8="Tier 2",BA8>=$AD8)),"ถึง 100%",IF(OR(AND(BD8=0,BA8>=$AC8*50%),AND(BD8="Tier 1",BA8>=$AC8*50%),AND(BD8="Tier 2",BA8>=$AD8*50%)),"ถึง 50%","ไม่ถึง 50%"))&IF(AND(BD8=0,OR(AZ8="เดือนที่ 1",AZ8="เดือนที่ 2"),BC8>=$AC8*50%)," และ FYC รวมถึง "&TEXT(BC8,"#,###")&" เข้ากฎเกณฑ์ข้อ 4",IF(AND(BE8=0,BC8>=$AC8,BC8<$AD8)," แม้ว่า FYC รวมจะถึง "&TEXT($AC8,"#,###")&" บาท ของ Tier 1",IF(AND(BE8=0,BC8>=$AC8,BC8>=$AD8)," แม้ว่า FYC รวมจะถึง "&TEXT($AD8,"#,###")&" บาท ของ Tier 2",IF(AND(BD8="Tier 1",BC8>=$AC8,BC8<$AD8)," ของ Tier 1 และ FYC รวมถึง "&TEXT($AC8,"#,###")&" บาท ของ Tier 1",IF(AND(BD8="Tier 1",BC8>=$AC8,BC8>=$AD8)," ของ Tier 1 แม้ว่า FYC รวมจะมากกว่า "&TEXT($AD8,"#,###")&" บาท ของ Tier 2",IF(AND(BD8="Tier 2",BC8>=$AC8,BC8>=$AD8)," ของ Tier 2 และ FYC รวมถึง "&TEXT($AD8,"#,###")&" บาท ของ Tier 2","")))))) -> ผลงานอนุมัติใหม่ถึง 100% ของ Tier 2 และ FYC รวมถึง 18,000 บาท ของ Tier 2 | BG8: 3 | BH8: =IF(BG8<=$P$4,SUM($BE$6:BE8),0) -> 0
C9: RYC3 | G9: =P9 -> 0.05 | H9: =$C$5*G9 -> 150000 | I9: =Q9 -> 0.035 | J9: =$C$5*I9 -> 105000 | K9: =R9 -> 0.025 | L9: =$C$5*K9 -> 75000 | O9: RYC4 | P9: 0.05 | Q9: 0.035 | R9: 0.025 | AA9: เดือน 4 | AC9: 10000 | AD9: 18000 | AF9: เดือนที่ 4 | AG9: =$H$6 -> 1200000 | AH9: 0 | AI9: =AG9+AH9 -> 1200000 | AJ9: =IF(AND(AG9>=$AD9*50%,AI9>=$AD9),"Tier 2",IF(AND(AG9>=$AC9*50%,AI9>=$AC9),"Tier 1",0)) -> Tier 2 | AK9: =IF(AJ9="Tier 2",20000,IF(AJ9="Tier 1",10000,IF(AND(OR(AF9="เดือนที่ 1",AF9="เดือนที่ 2"),AJ9=0,AG9>=$AB9),5000,0))) -> 20000 | AL9: ="ผลงานอนุมัติใหม่"&IF(OR(AND(AJ9="Tier 1",AG9>=$AC9),AND(AJ9="Tier 2",AG9>=$AD9)),"ถึง 100%",IF(OR(AND(AJ9=0,AG9>=$AC9*50%),AND(AJ9="Tier 1",AG9>=$AC9*50%),AND(AJ9="Tier 2",AG9>=$AD9*50%)),"ถึง 50%","ไม่ถึง 50%"))&IF(AND(AJ9=0,OR(AF9="เดือนที่ 1",AF9="เดือนที่ 2"),AI9>=$AC9*50%)," และ FYC รวมถึง "&TEXT(AI9,"#,###")&" เข้ากฎเกณฑ์ข้อ 4",IF(AND(AK9=0,AI9>=$AC9,AI9<$AD9)," แม้ว่า FYC รวมจะถึง "&TEXT($AC9,"#,###")&" บาท ของ Tier 1",IF(AND(AK9=0,AI9>=$AC9,AI9>=$AD9)," แม้ว่า FYC รวมจะถึง "&TEXT($AD9,"#,###")&" บาท ของ Tier 2",IF(AND(AJ9="Tier 1",AI9>=$AC9,AI9<$AD9)," ของ Tier 1 และ FYC รวมถึง "&TEXT($AC9,"#,###")&" บาท ของ Tier 1",IF(AND(AJ9="Tier 1",AI9>=$AC9,AI9>=$AD9)," ของ Tier 1 แม้ว่า FYC รวมจะมากกว่า "&TEXT($AD9,"#,###")&" บาท ของ Tier 2",IF(AND(AJ9="Tier 2",AI9>=$AC9,AI9>=$AD9)," ของ Tier 2 และ FYC รวมถึง "&TEXT($AD9,"#,###")&" บาท ของ Tier 2","")))))) -> ผลงานอนุมัติใหม่ถึง 100% ของ Tier 2 และ FYC รวมถึง 18,000 บาท ของ Tier 2 | AM9: 4 | AN9: =IF(AM9<=$P$4,SUM($AK$6:AK9),0) -> 0 | AP9: เดือนที่ 4 | AQ9: =$J$6 -> 1140000 | AR9: 0 | AS9: =AQ9+AR9 -> 1140000 | AT9: =IF(AND(AQ9>=$AD9*50%,AS9>=$AD9),"Tier 2",IF(AND(AQ9>=$AC9*50%,AS9>=$AC9),"Tier 1",0)) -> Tier 2 | AU9: =IF(AT9="Tier 2",20000,IF(AT9="Tier 1",10000,IF(AND(OR(AP9="เดือนที่ 1",AP9="เดือนที่ 2"),AT9=0,AQ9>=$AB9),5000,0))) -> 20000 | AV9: ="ผลงานอนุมัติใหม่"&IF(OR(AND(AT9="Tier 1",AQ9>=$AC9),AND(AT9="Tier 2",AQ9>=$AD9)),"ถึง 100%",IF(OR(AND(AT9=0,AQ9>=$AC9*50%),AND(AT9="Tier 1",AQ9>=$AC9*50%),AND(AT9="Tier 2",AQ9>=$AD9*50%)),"ถึง 50%","ไม่ถึง 50%"))&IF(AND(AT9=0,OR(AP9="เดือนที่ 1",AP9="เดือนที่ 2"),AS9>=$AC9*50%)," และ FYC รวมถึง "&TEXT(AS9,"#,###")&" เข้ากฎเกณฑ์ข้อ 4",IF(AND(AU9=0,AS9>=$AC9,AS9<$AD9)," แม้ว่า FYC รวมจะถึง "&TEXT($AC9,"#,###")&" บาท ของ Tier 1",IF(AND(AU9=0,AS9>=$AC9,AS9>=$AD9)," แม้ว่า FYC รวมจะถึง "&TEXT($AD9,"#,###")&" บาท ของ Tier 2",IF(AND(AT9="Tier 1",AS9>=$AC9,AS9<$AD9)," ของ Tier 1 และ FYC รวมถึง "&TEXT($AC9,"#,###")&" บาท ของ Tier 1",IF(AND(AT9="Tier 1",AS9>=$AC9,AS9>=$AD9)," ของ Tier 1 แม้ว่า FYC รวมจะมากกว่า "&TEXT($AD9,"#,###")&" บาท ของ Tier 2",IF(AND(AT9="Tier 2",AS9>=$AC9,AS9>=$AD9)," ของ Tier 2 และ FYC รวมถึง "&TEXT($AD9,"#,###")&" บาท ของ Tier 2","")))))) -> ผลงานอนุมัติใหม่ถึง 100% ของ Tier 2 และ FYC รวมถึง 18,000 บาท ของ Tier 2 | AW9: 4 | AX9: =IF(AW9<=$P$4,SUM($AU$6:AU9),0) -> 0 | AZ9: เดือนที่ 4 | BA9: =$L$6 -> 900000 | BB9: 0 | BC9: =BA9+BB9 -> 900000 | BD9: =IF(AND(BA9>=$AD9*50%,BC9>=$AD9),"Tier 2",IF(AND(BA9>=$AC9*50%,BC9>=$AC9),"Tier 1",0)) -> Tier 2 | BE9: =IF(BD9="Tier 2",20000,IF(BD9="Tier 1",10000,IF(AND(OR(AZ9="เดือนที่ 1",AZ9="เดือนที่ 2"),BD9=0,BA9>=$AB9),5000,0))) -> 20000 | BF9: ="ผลงานอนุมัติใหม่"&IF(OR(AND(BD9="Tier 1",BA9>=$AC9),AND(BD9="Tier 2",BA9>=$AD9)),"ถึง 100%",IF(OR(AND(BD9=0,BA9>=$AC9*50%),AND(BD9="Tier 1",BA9>=$AC9*50%),AND(BD9="Tier 2",BA9>=$AD9*50%)),"ถึง 50%","ไม่ถึง 50%"))&IF(AND(BD9=0,OR(AZ9="เดือนที่ 1",AZ9="เดือนที่ 2"),BC9>=$AC9*50%)," และ FYC รวมถึง "&TEXT(BC9,"#,###")&" เข้ากฎเกณฑ์ข้อ 4",IF(AND(BE9=0,BC9>=$AC9,BC9<$AD9)," แม้ว่า FYC รวมจะถึง "&TEXT($AC9,"#,###")&" บาท ของ Tier 1",IF(AND(BE9=0,BC9>=$AC9,BC9>=$AD9)," แม้ว่า FYC รวมจะถึง "&TEXT($AD9,"#,###")&" บาท ของ Tier 2",IF(AND(BD9="Tier 1",BC9>=$AC9,BC9<$AD9)," ของ Tier 1 และ FYC รวมถึง "&TEXT($AC9,"#,###")&" บาท ของ Tier 1",IF(AND(BD9="Tier 1",BC9>=$AC9,BC9>=$AD9)," ของ Tier 1 แม้ว่า FYC รวมจะมากกว่า "&TEXT($AD9,"#,###")&" บาท ของ Tier 2",IF(AND(BD9="Tier 2",BC9>=$AC9,BC9>=$AD9)," ของ Tier 2 และ FYC รวมถึง "&TEXT($AD9,"#,###")&" บาท ของ Tier 2","")))))) -> ผลงานอนุมัติใหม่ถึง 100% ของ Tier 2 และ FYC รวมถึง 18,000 บาท ของ Tier 2 | BG9: 4 | BH9: =IF(BG9<=$P$4,SUM($BE$6:BE9),0) -> 0
C10: RYC4 | G10: =P10 -> 0.05 | H10: =$C$5*G10 -> 150000 | I10: =Q10 -> 0.035 | J10: =$C$5*I10 -> 105000 | K10: =R10 -> 0.025 | L10: =$C$5*K10 -> 75000 | O10: RYC5 | P10: 0.05 | Q10: 0.035 | R10: 0.025 | AA10: เดือน 5 | AC10: 15000 | AD10: 30000 | AF10: เดือนที่ 5 | AG10: =$H$6 -> 1200000 | AH10: 0 | AI10: =AG10+AH10 -> 1200000 | AJ10: =IF(AND(AG10>=$AD10*50%,AI10>=$AD10),"Tier 2",IF(AND(AG10>=$AC10*50%,AI10>=$AC10),"Tier 1",0)) -> Tier 2 | AK10: =IF(AJ10="Tier 2",20000,IF(AJ10="Tier 1",10000,IF(AND(OR(AF10="เดือนที่ 1",AF10="เดือนที่ 2"),AJ10=0,AG10>=$AB10),5000,0))) -> 20000 | AL10: ="ผลงานอนุมัติใหม่"&IF(OR(AND(AJ10="Tier 1",AG10>=$AC10),AND(AJ10="Tier 2",AG10>=$AD10)),"ถึง 100%",IF(OR(AND(AJ10=0,AG10>=$AC10*50%),AND(AJ10="Tier 1",AG10>=$AC10*50%),AND(AJ10="Tier 2",AG10>=$AD10*50%)),"ถึง 50%","ไม่ถึง 50%"))&IF(AND(AJ10=0,OR(AF10="เดือนที่ 1",AF10="เดือนที่ 2"),AI10>=$AC10*50%)," และ FYC รวมถึง "&TEXT(AI10,"#,###")&" เข้ากฎเกณฑ์ข้อ 4",IF(AND(AK10=0,AI10>=$AC10,AI10<$AD10)," แม้ว่า FYC รวมจะถึง "&TEXT($AC10,"#,###")&" บาท ของ Tier 1",IF(AND(AK10=0,AI10>=$AC10,AI10>=$AD10)," แม้ว่า FYC รวมจะถึง "&TEXT($AD10,"#,###")&" บาท ของ Tier 2",IF(AND(AJ10="Tier 1",AI10>=$AC10,AI10<$AD10)," ของ Tier 1 และ FYC รวมถึง "&TEXT($AC10,"#,###")&" บาท ของ Tier 1",IF(AND(AJ10="Tier 1",AI10>=$AC10,AI10>=$AD10)," ของ Tier 1 แม้ว่า FYC รวมจะมากกว่า "&TEXT($AD10,"#,###")&" บาท ของ Tier 2",IF(AND(AJ10="Tier 2",AI10>=$AC10,AI10>=$AD10)," ของ Tier 2 และ FYC รวมถึง "&TEXT($AD10,"#,###")&" บาท ของ Tier 2","")))))) -> ผลงานอนุมัติใหม่ถึง 100% ของ Tier 2 และ FYC รวมถึง 30,000 บาท ของ Tier 2 | AM10: 5 | AN10: =IF(AM10<=$P$4,SUM($AK$6:AK10),0) -> 0 | AP10: เดือนที่ 5 | AQ10: =$J$6 -> 1140000 | AR10: 0 | AS10: =AQ10+AR10 -> 1140000 | AT10: =IF(AND(AQ10>=$AD10*50%,AS10>=$AD10),"Tier 2",IF(AND(AQ10>=$AC10*50%,AS10>=$AC10),"Tier 1",0)) -> Tier 2 | AU10: =IF(AT10="Tier 2",20000,IF(AT10="Tier 1",10000,IF(AND(OR(AP10="เดือนที่ 1",AP10="เดือนที่ 2"),AT10=0,AQ10>=$AB10),5000,0))) -> 20000 | AV10: ="ผลงานอนุมัติใหม่"&IF(OR(AND(AT10="Tier 1",AQ10>=$AC10),AND(AT10="Tier 2",AQ10>=$AD10)),"ถึง 100%",IF(OR(AND(AT10=0,AQ10>=$AC10*50%),AND(AT10="Tier 1",AQ10>=$AC10*50%),AND(AT10="Tier 2",AQ10>=$AD10*50%)),"ถึง 50%","ไม่ถึง 50%"))&IF(AND(AT10=0,OR(AP10="เดือนที่ 1",AP10="เดือนที่ 2"),AS10>=$AC10*50%)," และ FYC รวมถึง "&TEXT(AS10,"#,###")&" เข้ากฎเกณฑ์ข้อ 4",IF(AND(AU10=0,AS10>=$AC10,AS10<$AD10)," แม้ว่า FYC รวมจะถึง "&TEXT($AC10,"#,###")&" บาท ของ Tier 1",IF(AND(AU10=0,AS10>=$AC10,AS10>=$AD10)," แม้ว่า FYC รวมจะถึง "&TEXT($AD10,"#,###")&" บาท ของ Tier 2",IF(AND(AT10="Tier 1",AS10>=$AC10,AS10<$AD10)," ของ Tier 1 และ FYC รวมถึง "&TEXT($AC10,"#,###")&" บาท ของ Tier 1",IF(AND(AT10="Tier 1",AS10>=$AC10,AS10>=$AD10)," ของ Tier 1 แม้ว่า FYC รวมจะมากกว่า "&TEXT($AD10,"#,###")&" บาท ของ Tier 2",IF(AND(AT10="Tier 2",AS10>=$AC10,AS10>=$AD10)," ของ Tier 2 และ FYC รวมถึง "&TEXT($AD10,"#,###")&" บาท ของ Tier 2","")))))) -> ผลงานอนุมัติใหม่ถึง 100% ของ Tier 2 และ FYC รวมถึง 30,000 บาท ของ Tier 2 | AW10: 5 | AX10: =IF(AW10<=$P$4,SUM($AU$6:AU10),0) -> 0 | AZ10: เดือนที่ 5 | BA10: =$L$6 -> 900000 | BB10: 0 | BC10: =BA10+BB10 -> 900000 | BD10: =IF(AND(BA10>=$AD10*50%,BC10>=$AD10),"Tier 2",IF(AND(BA10>=$AC10*50%,BC10>=$AC10),"Tier 1",0)) -> Tier 2 | BE10: =IF(BD10="Tier 2",20000,IF(BD10="Tier 1",10000,IF(AND(OR(AZ10="เดือนที่ 1",AZ10="เดือนที่ 2"),BD10=0,BA10>=$AB10),5000,0))) -> 20000 | BF10: ="ผลงานอนุมัติใหม่"&IF(OR(AND(BD10="Tier 1",BA10>=$AC10),AND(BD10="Tier 2",BA10>=$AD10)),"ถึง 100%",IF(OR(AND(BD10=0,BA10>=$AC10*50%),AND(BD10="Tier 1",BA10>=$AC10*50%),AND(BD10="Tier 2",BA10>=$AD10*50%)),"ถึง 50%","ไม่ถึง 50%"))&IF(AND(BD10=0,OR(AZ10="เดือนที่ 1",AZ10="เดือนที่ 2"),BC10>=$AC10*50%)," และ FYC รวมถึง "&TEXT(BC10,"#,###")&" เข้ากฎเกณฑ์ข้อ 4",IF(AND(BE10=0,BC10>=$AC10,BC10<$AD10)," แม้ว่า FYC รวมจะถึง "&TEXT($AC10,"#,###")&" บาท ของ Tier 1",IF(AND(BE10=0,BC10>=$AC10,BC10>=$AD10)," แม้ว่า FYC รวมจะถึง "&TEXT($AD10,"#,###")&" บาท ของ Tier 2",IF(AND(BD10="Tier 1",BC10>=$AC10,BC10<$AD10)," ของ Tier 1 และ FYC รวมถึง "&TEXT($AC10,"#,###")&" บาท ของ Tier 1",IF(AND(BD10="Tier 1",BC10>=$AC10,BC10>=$AD10)," ของ Tier 1 แม้ว่า FYC รวมจะมากกว่า "&TEXT($AD10,"#,###")&" บาท ของ Tier 2",IF(AND(BD10="Tier 2",BC10>=$AC10,BC10>=$AD10)," ของ Tier 2 และ FYC รวมถึง "&TEXT($AD10,"#,###")&" บาท ของ Tier 2","")))))) -> ผลงานอนุมัติใหม่ถึง 100% ของ Tier 2 และ FYC รวมถึง 30,000 บาท ของ Tier 2 | BG10: 5 | BH10: =IF(BG10<=$P$4,SUM($BE$6:BE10),0) -> 0
B11: Bonus | D11: FYC สะสม | F11: อัตรา | G11: ผลงาน | H11: =P4 -> 0.75 | I11: ผลงาน | J11: =Q4 -> 0.75 | K11: ผลงาน | L11: =R4 -> 1 | O11: K2 | P11: 0.75 | Q11: 0.75 | R11: 0.75 | AA11: เดือน 7 | AC11: 15000 | AD11: 30000 | AF11: เดือนที่ 7 | AG11: =$H$6 -> 1200000 | AH11: 0 | AI11: =AG11+AH11 -> 1200000 | AJ11: =IF(AND(AG11>=$AD11*50%,AI11>=$AD11),"Tier 2",IF(AND(AG11>=$AC11*50%,AI11>=$AC11),"Tier 1",0)) -> Tier 2 | AK11: =IF(AJ11="Tier 2",20000,IF(AJ11="Tier 1",10000,IF(AND(OR(AF11="เดือนที่ 1",AF11="เดือนที่ 2"),AJ11=0,AG11>=$AB11),5000,0))) -> 20000 | AL11: ="ผลงานอนุมัติใหม่"&IF(OR(AND(AJ11="Tier 1",AG11>=$AC11),AND(AJ11="Tier 2",AG11>=$AD11)),"ถึง 100%",IF(OR(AND(AJ11=0,AG11>=$AC11*50%),AND(AJ11="Tier 1",AG11>=$AC11*50%),AND(AJ11="Tier 2",AG11>=$AD11*50%)),"ถึง 50%","ไม่ถึง 50%"))&IF(AND(AJ11=0,OR(AF11="เดือนที่ 1",AF11="เดือนที่ 2"),AI11>=$AC11*50%)," และ FYC รวมถึง "&TEXT(AI11,"#,###")&" เข้ากฎเกณฑ์ข้อ 4",IF(AND(AK11=0,AI11>=$AC11,AI11<$AD11)," แม้ว่า FYC รวมจะถึง "&TEXT($AC11,"#,###")&" บาท ของ Tier 1",IF(AND(AK11=0,AI11>=$AC11,AI11>=$AD11)," แม้ว่า FYC รวมจะถึง "&TEXT($AD11,"#,###")&" บาท ของ Tier 2",IF(AND(AJ11="Tier 1",AI11>=$AC11,AI11<$AD11)," ของ Tier 1 และ FYC รวมถึง "&TEXT($AC11,"#,###")&" บาท ของ Tier 1",IF(AND(AJ11="Tier 1",AI11>=$AC11,AI11>=$AD11)," ของ Tier 1 แม้ว่า FYC รวมจะมากกว่า "&TEXT($AD11,"#,###")&" บาท ของ Tier 2",IF(AND(AJ11="Tier 2",AI11>=$AC11,AI11>=$AD11)," ของ Tier 2 และ FYC รวมถึง "&TEXT($AD11,"#,###")&" บาท ของ Tier 2","")))))) -> ผลงานอนุมัติใหม่ถึง 100% ของ Tier 2 และ FYC รวมถึง 30,000 บาท ของ Tier 2 | AM11: 7 | AN11: =IF(AM11<=$P$4,SUM($AK$6:AK11),0) -> 0 | AP11: เดือนที่ 7 | AQ11: =$J$6 -> 1140000 | AR11: 0 | AS11: =AQ11+AR11 -> 1140000 | AT11: =IF(AND(AQ11>=$AD11*50%,AS11>=$AD11),"Tier 2",IF(AND(AQ11>=$AC11*50%,AS11>=$AC11),"Tier 1",0)) -> Tier 2 | AU11: =IF(AT11="Tier 2",20000,IF(AT11="Tier 1",10000,IF(AND(OR(AP11="เดือนที่ 1",AP11="เดือนที่ 2"),AT11=0,AQ11>=$AB11),5000,0))) -> 20000 | AV11: ="ผลงานอนุมัติใหม่"&IF(OR(AND(AT11="Tier 1",AQ11>=$AC11),AND(AT11="Tier 2",AQ11>=$AD11)),"ถึง 100%",IF(OR(AND(AT11=0,AQ11>=$AC11*50%),AND(AT11="Tier 1",AQ11>=$AC11*50%),AND(AT11="Tier 2",AQ11>=$AD11*50%)),"ถึง 50%","ไม่ถึง 50%"))&IF(AND(AT11=0,OR(AP11="เดือนที่ 1",AP11="เดือนที่ 2"),AS11>=$AC11*50%)," และ FYC รวมถึง "&TEXT(AS11,"#,###")&" เข้ากฎเกณฑ์ข้อ 4",IF(AND(AU11=0,AS11>=$AC11,AS11<$AD11)," แม้ว่า FYC รวมจะถึง "&TEXT($AC11,"#,###")&" บาท ของ Tier 1",IF(AND(AU11=0,AS11>=$AC11,AS11>=$AD11)," แม้ว่า FYC รวมจะถึง "&TEXT($AD11,"#,###")&" บาท ของ Tier 2",IF(AND(AT11="Tier 1",AS11>=$AC11,AS11<$AD11)," ของ Tier 1 และ FYC รวมถึง "&TEXT($AC11,"#,###")&" บาท ของ Tier 1",IF(AND(AT11="Tier 1",AS11>=$AC11,AS11>=$AD11)," ของ Tier 1 แม้ว่า FYC รวมจะมากกว่า "&TEXT($AD11,"#,###")&" บาท ของ Tier 2",IF(AND(AT11="Tier 2",AS11>=$AC11,AS11>=$AD11)," ของ Tier 2 และ FYC รวมถึง "&TEXT($AD11,"#,###")&" บาท ของ Tier 2","")))))) -> ผลงานอนุมัติใหม่ถึง 100% ของ Tier 2 และ FYC รวมถึง 30,000 บาท ของ Tier 2 | AW11: 7 | AX11: =IF(AW11<=$P$4,SUM($AU$6:AU11),0) -> 0 | AZ11: เดือนที่ 7 | BA11: =$L$6 -> 900000 | BB11: 0 | BC11: =BA11+BB11 -> 900000 | BD11: =IF(AND(BA11>=$AD11*50%,BC11>=$AD11),"Tier 2",IF(AND(BA11>=$AC11*50%,BC11>=$AC11),"Tier 1",0)) -> Tier 2 | BE11: =IF(BD11="Tier 2",20000,IF(BD11="Tier 1",10000,IF(AND(OR(AZ11="เดือนที่ 1",AZ11="เดือนที่ 2"),BD11=0,BA11>=$AB11),5000,0))) -> 20000 | BF11: ="ผลงานอนุมัติใหม่"&IF(OR(AND(BD11="Tier 1",BA11>=$AC11),AND(BD11="Tier 2",BA11>=$AD11)),"ถึง 100%",IF(OR(AND(BD11=0,BA11>=$AC11*50%),AND(BD11="Tier 1",BA11>=$AC11*50%),AND(BD11="Tier 2",BA11>=$AD11*50%)),"ถึง 50%","ไม่ถึง 50%"))&IF(AND(BD11=0,OR(AZ11="เดือนที่ 1",AZ11="เดือนที่ 2"),BC11>=$AC11*50%)," และ FYC รวมถึง "&TEXT(BC11,"#,###")&" เข้ากฎเกณฑ์ข้อ 4",IF(AND(BE11=0,BC11>=$AC11,BC11<$AD11)," แม้ว่า FYC รวมจะถึง "&TEXT($AC11,"#,###")&" บาท ของ Tier 1",IF(AND(BE11=0,BC11>=$AC11,BC11>=$AD11)," แม้ว่า FYC รวมจะถึง "&TEXT($AD11,"#,###")&" บาท ของ Tier 2",IF(AND(BD11="Tier 1",BC11>=$AC11,BC11<$AD11)," ของ Tier 1 และ FYC รวมถึง "&TEXT($AC11,"#,###")&" บาท ของ Tier 1",IF(AND(BD11="Tier 1",BC11>=$AC11,BC11>=$AD11)," ของ Tier 1 แม้ว่า FYC รวมจะมากกว่า "&TEXT($AD11,"#,###")&" บาท ของ Tier 2",IF(AND(BD11="Tier 2",BC11>=$AC11,BC11>=$AD11)," ของ Tier 2 และ FYC รวมถึง "&TEXT($AD11,"#,###")&" บาท ของ Tier 2","")))))) -> ผลงานอนุมัติใหม่ถึง 100% ของ Tier 2 และ FYC รวมถึง 30,000 บาท ของ Tier 2 | BG11: 7 | BH11: =IF(BG11<=$P$4,SUM($BE$6:BE11),0) -> 0
G12: K2 | H12: =P11 -> 0.75 | I12: K2 | J12: =Q11 -> 0.75 | K12: K2 | L12: =R11 -> 0.75 | AA12: เดือน 8 | AC12: 15000 | AD12: 30000 | AF12: เดือนที่ 8 | AG12: =$H$6 -> 1200000 | AH12: 0 | AI12: =AG12+AH12 -> 1200000 | AJ12: =IF(AND(AG12>=$AD12*50%,AI12>=$AD12),"Tier 2",IF(AND(AG12>=$AC12*50%,AI12>=$AC12),"Tier 1",0)) -> Tier 2 | AK12: =IF(AJ12="Tier 2",20000,IF(AJ12="Tier 1",10000,IF(AND(OR(AF12="เดือนที่ 1",AF12="เดือนที่ 2"),AJ12=0,AG12>=$AB12),5000,0))) -> 20000 | AL12: ="ผลงานอนุมัติใหม่"&IF(OR(AND(AJ12="Tier 1",AG12>=$AC12),AND(AJ12="Tier 2",AG12>=$AD12)),"ถึง 100%",IF(OR(AND(AJ12=0,AG12>=$AC12*50%),AND(AJ12="Tier 1",AG12>=$AC12*50%),AND(AJ12="Tier 2",AG12>=$AD12*50%)),"ถึง 50%","ไม่ถึง 50%"))&IF(AND(AJ12=0,OR(AF12="เดือนที่ 1",AF12="เดือนที่ 2"),AI12>=$AC12*50%)," และ FYC รวมถึง "&TEXT(AI12,"#,###")&" เข้ากฎเกณฑ์ข้อ 4",IF(AND(AK12=0,AI12>=$AC12,AI12<$AD12)," แม้ว่า FYC รวมจะถึง "&TEXT($AC12,"#,###")&" บาท ของ Tier 1",IF(AND(AK12=0,AI12>=$AC12,AI12>=$AD12)," แม้ว่า FYC รวมจะถึง "&TEXT($AD12,"#,###")&" บาท ของ Tier 2",IF(AND(AJ12="Tier 1",AI12>=$AC12,AI12<$AD12)," ของ Tier 1 และ FYC รวมถึง "&TEXT($AC12,"#,###")&" บาท ของ Tier 1",IF(AND(AJ12="Tier 1",AI12>=$AC12,AI12>=$AD12)," ของ Tier 1 แม้ว่า FYC รวมจะมากกว่า "&TEXT($AD12,"#,###")&" บาท ของ Tier 2",IF(AND(AJ12="Tier 2",AI12>=$AC12,AI12>=$AD12)," ของ Tier 2 และ FYC รวมถึง "&TEXT($AD12,"#,###")&" บาท ของ Tier 2","")))))) -> ผลงานอนุมัติใหม่ถึง 100% ของ Tier 2 และ FYC รวมถึง 30,000 บาท ของ Tier 2 | AM12: 8 | AN12: =IF(AM12<=$P$4,SUM($AK$6:AK12),0) -> 0 | AP12: เดือนที่ 8 | AQ12: =$J$6 -> 1140000 | AR12: 0 | AS12: =AQ12+AR12 -> 1140000 | AT12: =IF(AND(AQ12>=$AD12*50%,AS12>=$AD12),"Tier 2",IF(AND(AQ12>=$AC12*50%,AS12>=$AC12),"Tier 1",0)) -> Tier 2 | AU12: =IF(AT12="Tier 2",20000,IF(AT12="Tier 1",10000,IF(AND(OR(AP12="เดือนที่ 1",AP12="เดือนที่ 2"),AT12=0,AQ12>=$AB12),5000,0))) -> 20000 | AV12: ="ผลงานอนุมัติใหม่"&IF(OR(AND(AT12="Tier 1",AQ12>=$AC12),AND(AT12="Tier 2",AQ12>=$AD12)),"ถึง 100%",IF(OR(AND(AT12=0,AQ12>=$AC12*50%),AND(AT12="Tier 1",AQ12>=$AC12*50%),AND(AT12="Tier 2",AQ12>=$AD12*50%)),"ถึง 50%","ไม่ถึง 50%"))&IF(AND(AT12=0,OR(AP12="เดือนที่ 1",AP12="เดือนที่ 2"),AS12>=$AC12*50%)," และ FYC รวมถึง "&TEXT(AS12,"#,###")&" เข้ากฎเกณฑ์ข้อ 4",IF(AND(AU12=0,AS12>=$AC12,AS12<$AD12)," แม้ว่า FYC รวมจะถึง "&TEXT($AC12,"#,###")&" บาท ของ Tier 1",IF(AND(AU12=0,AS12>=$AC12,AS12>=$AD12)," แม้ว่า FYC รวมจะถึง "&TEXT($AD12,"#,###")&" บาท ของ Tier 2",IF(AND(AT12="Tier 1",AS12>=$AC12,AS12<$AD12)," ของ Tier 1 และ FYC รวมถึง "&TEXT($AC12,"#,###")&" บาท ของ Tier 1",IF(AND(AT12="Tier 1",AS12>=$AC12,AS12>=$AD12)," ของ Tier 1 แม้ว่า FYC รวมจะมากกว่า "&TEXT($AD12,"#,###")&" บาท ของ Tier 2",IF(AND(AT12="Tier 2",AS12>=$AC12,AS12>=$AD12)," ของ Tier 2 และ FYC รวมถึง "&TEXT($AD12,"#,###")&" บาท ของ Tier 2","")))))) -> ผลงานอนุมัติใหม่ถึง 100% ของ Tier 2 และ FYC รวมถึง 30,000 บาท ของ Tier 2 | AW12: 8 | AX12: =IF(AW12<=$P$4,SUM($AU$6:AU12),0) -> 0 | AZ12: เดือนที่ 8 | BA12: =$L$6 -> 900000 | BB12: 0 | BC12: =BA12+BB12 -> 900000 | BD12: =IF(AND(BA12>=$AD12*50%,BC12>=$AD12),"Tier 2",IF(AND(BA12>=$AC12*50%,BC12>=$AC12),"Tier 1",0)) -> Tier 2 | BE12: =IF(BD12="Tier 2",20000,IF(BD12="Tier 1",10000,IF(AND(OR(AZ12="เดือนที่ 1",AZ12="เดือนที่ 2"),BD12=0,BA12>=$AB12),5000,0))) -> 20000 | BF12: ="ผลงานอนุมัติใหม่"&IF(OR(AND(BD12="Tier 1",BA12>=$AC12),AND(BD12="Tier 2",BA12>=$AD12)),"ถึง 100%",IF(OR(AND(BD12=0,BA12>=$AC12*50%),AND(BD12="Tier 1",BA12>=$AC12*50%),AND(BD12="Tier 2",BA12>=$AD12*50%)),"ถึง 50%","ไม่ถึง 50%"))&IF(AND(BD12=0,OR(AZ12="เดือนที่ 1",AZ12="เดือนที่ 2"),BC12>=$AC12*50%)," และ FYC รวมถึง "&TEXT(BC12,"#,###")&" เข้ากฎเกณฑ์ข้อ 4",IF(AND(BE12=0,BC12>=$AC12,BC12<$AD12)," แม้ว่า FYC รวมจะถึง "&TEXT($AC12,"#,###")&" บาท ของ Tier 1",IF(AND(BE12=0,BC12>=$AC12,BC12>=$AD12)," แม้ว่า FYC รวมจะถึง "&TEXT($AD12,"#,###")&" บาท ของ Tier 2",IF(AND(BD12="Tier 1",BC12>=$AC12,BC12<$AD12)," ของ Tier 1 และ FYC รวมถึง "&TEXT($AC12,"#,###")&" บาท ของ Tier 1",IF(AND(BD12="Tier 1",BC12>=$AC12,BC12>=$AD12)," ของ Tier 1 แม้ว่า FYC รวมจะมากกว่า "&TEXT($AD12,"#,###")&" บาท ของ Tier 2",IF(AND(BD12="Tier 2",BC12>=$AC12,BC12>=$AD12)," ของ Tier 2 และ FYC รวมถึง "&TEXT($AD12,"#,###")&" บาท ของ Tier 2","")))))) -> ผลงานอนุมัติใหม่ถึง 100% ของ Tier 2 และ FYC รวมถึง 30,000 บาท ของ Tier 2 | BG12: 8 | BH12: =IF(BG12<=$P$4,SUM($BE$6:BE12),0) -> 0
B13: 2 | C13: โบนัสรายเดือน (MB) | D13: 8,000 - 16,000 | F13: 0.2 | G13: =IF($P$11<70%,0,IF(H$6*$P$4/12>64000,"35%", IF(AND(H$6*$P$4/12>32000,H$6*$P$4/12<=64000),"30%", IF(AND(H$6*$P$4/12>16000,H$6*$P$4/12<=32000),"25%", IF(AND(H$6*$P$4/12>8000,H$6*$P$4/12<=16000),"20%", 0))))) -> 35% | H13: =H6*$P$4*G13 -> 315000 | I13: =IF($Q$11<70%,0,IF(J$6*$Q$4/12>64000,"35%", IF(AND(J$6*$Q$4/12>32000,J$6*$Q$4/12<=64000),"30%", IF(AND(J$6*$Q$4/12>16000,J$6*$Q$4/12<=32000),"25%", IF(AND(J$6*$Q$4/12>8000,J$6*$Q$4/12<=16000),"20%", 0))))) -> 35% | J13: =J6*$Q$4*I13 -> 299250 | K13: =IF($R$11<70%,0,IF(L$6*$R$4/12>64000,"35%", IF(AND(L$6*$R$4/12>32000,L$6*$R$4/12<=64000),"30%", IF(AND(L$6*$R$4/12>16000,L$6*$R$4/12<=32000),"25%", IF(AND(L$6*$R$4/12>8000,L$6*$R$4/12<=16000),"20%", 0))))) -> 35% | L13: =L6*$R$4*K13 -> 315000
D14: 16,001 - 32,000 | F14: 0.25
D15: 32,001 - 64,000 | F15: 0.3
D16: 64,001 เป็นต้นไป | F16: 0.35 | AA16: เดือน 11 | AC16: 15000 | AD16: 30000 | AF16: เดือนที่ 11 | AG16: =$H$6 -> 1200000 | AH16: 0 | AI16: =AG16+AH16 -> 1200000 | AJ16: =IF(AND(AG16>=$AD16*50%,AI16>=$AD16),"Tier 2",IF(AND(AG16>=$AC16*50%,AI16>=$AC16),"Tier 1",0)) -> Tier 2 | AK16: =IF(AJ16="Tier 2",20000,IF(AJ16="Tier 1",10000,IF(AND(OR(AF16="เดือนที่ 1",AF16="เดือนที่ 2"),AJ16=0,AG16>=$AB16),5000,0))) -> 20000 | AL16: ="ผลงานอนุมัติใหม่"&IF(OR(AND(AJ16="Tier 1",AG16>=$AC16),AND(AJ16="Tier 2",AG16>=$AD16)),"ถึง 100%",IF(OR(AND(AJ16=0,AG16>=$AC16*50%),AND(AJ16="Tier 1",AG16>=$AC16*50%),AND(AJ16="Tier 2",AG16>=$AD16*50%)),"ถึง 50%","ไม่ถึง 50%"))&IF(AND(AJ16=0,OR(AF16="เดือนที่ 1",AF16="เดือนที่ 2"),AI16>=$AC16*50%)," และ FYC รวมถึง "&TEXT(AI16,"#,###")&" เข้ากฎเกณฑ์ข้อ 4",IF(AND(AK16=0,AI16>=$AC16,AI16<$AD16)," แม้ว่า FYC รวมจะถึง "&TEXT($AC16,"#,###")&" บาท ของ Tier 1",IF(AND(AK16=0,AI16>=$AC16,AI16>=$AD16)," แม้ว่า FYC รวมจะถึง "&TEXT($AD16,"#,###")&" บาท ของ Tier 2",IF(AND(AJ16="Tier 1",AI16>=$AC16,AI16<$AD16)," ของ Tier 1 และ FYC รวมถึง "&TEXT($AC16,"#,###")&" บาท ของ Tier 1",IF(AND(AJ16="Tier 1",AI16>=$AC16,AI16>=$AD16)," ของ Tier 1 แม้ว่า FYC รวมจะมากกว่า "&TEXT($AD16,"#,###")&" บาท ของ Tier 2",IF(AND(AJ16="Tier 2",AI16>=$AC16,AI16>=$AD16)," ของ Tier 2 และ FYC รวมถึง "&TEXT($AD16,"#,###")&" บาท ของ Tier 2","")))))) -> ผลงานอนุมัติใหม่ถึง 100% ของ Tier 2 และ FYC รวมถึง 30,000 บาท ของ Tier 2 | AM16: 11 | AN16: =IF(AM16<=$P$4,SUM($AK$6:AK16),0) -> 0 | AP16: เดือนที่ 11 | AQ16: =$J$6 -> 1140000 | AR16: 0 | AS16: =AQ16+AR16 -> 1140000 | AT16: =IF(AND(AQ16>=$AD16*50%,AS16>=$AD16),"Tier 2",IF(AND(AQ16>=$AC16*50%,AS16>=$AC16),"Tier 1",0)) -> Tier 2 | AU16: =IF(AT16="Tier 2",20000,IF(AT16="Tier 1",10000,IF(AND(OR(AP16="เดือนที่ 1",AP16="เดือนที่ 2"),AT16=0,AQ16>=$AB16),5000,0))) -> 20000 | AV16: ="ผลงานอนุมัติใหม่"&IF(OR(AND(AT16="Tier 1",AQ16>=$AC16),AND(AT16="Tier 2",AQ16>=$AD16)),"ถึง 100%",IF(OR(AND(AT16=0,AQ16>=$AC16*50%),AND(AT16="Tier 1",AQ16>=$AC16*50%),AND(AT16="Tier 2",AQ16>=$AD16*50%)),"ถึง 50%","ไม่ถึง 50%"))&IF(AND(AT16=0,OR(AP16="เดือนที่ 1",AP16="เดือนที่ 2"),AS16>=$AC16*50%)," และ FYC รวมถึง "&TEXT(AS16,"#,###")&" เข้ากฎเกณฑ์ข้อ 4",IF(AND(AU16=0,AS16>=$AC16,AS16<$AD16)," แม้ว่า FYC รวมจะถึง "&TEXT($AC16,"#,###")&" บาท ของ Tier 1",IF(AND(AU16=0,AS16>=$AC16,AS16>=$AD16)," แม้ว่า FYC รวมจะถึง "&TEXT($AD16,"#,###")&" บาท ของ Tier 2",IF(AND(AT16="Tier 1",AS16>=$AC16,AS16<$AD16)," ของ Tier 1 และ FYC รวมถึง "&TEXT($AC16,"#,###")&" บาท ของ Tier 1",IF(AND(AT16="Tier 1",AS16>=$AC16,AS16>=$AD16)," ของ Tier 1 แม้ว่า FYC รวมจะมากกว่า "&TEXT($AD16,"#,###")&" บาท ของ Tier 2",IF(AND(AT16="Tier 2",AS16>=$AC16,AS16>=$AD16)," ของ Tier 2 และ FYC รวมถึง "&TEXT($AD16,"#,###")&" บาท ของ Tier 2","")))))) -> ผลงานอนุมัติใหม่ถึง 100% ของ Tier 2 และ FYC รวมถึง 30,000 บาท ของ Tier 2 | AW16: 11 | AX16: =IF(AW16<=$P$4,SUM($AU$6:AU16),0) -> 0 | AZ16: เดือนที่ 11 | BA16: =$L$6 -> 900000 | BB16: 0 | BC16: =BA16+BB16 -> 900000 | BD16: =IF(AND(BA16>=$AD16*50%,BC16>=$AD16),"Tier 2",IF(AND(BA16>=$AC16*50%,BC16>=$AC16),"Tier 1",0)) -> Tier 2 | BE16: =IF(BD16="Tier 2",20000,IF(BD16="Tier 1",10000,IF(AND(OR(AZ16="เดือนที่ 1",AZ16="เดือนที่ 2"),BD16=0,BA16>=$AB16),5000,0))) -> 20000 | BF16: ="ผลงานอนุมัติใหม่"&IF(OR(AND(BD16="Tier 1",BA16>=$AC16),AND(BD16="Tier 2",BA16>=$AD16)),"ถึง 100%",IF(OR(AND(BD16=0,BA16>=$AC16*50%),AND(BD16="Tier 1",BA16>=$AC16*50%),AND(BD16="Tier 2",BA16>=$AD16*50%)),"ถึง 50%","ไม่ถึง 50%"))&IF(AND(BD16=0,OR(AZ16="เดือนที่ 1",AZ16="เดือนที่ 2"),BC16>=$AC16*50%)," และ FYC รวมถึง "&TEXT(BC16,"#,###")&" เข้ากฎเกณฑ์ข้อ 4",IF(AND(BE16=0,BC16>=$AC16,BC16<$AD16)," แม้ว่า FYC รวมจะถึง "&TEXT($AC16,"#,###")&" บาท ของ Tier 1",IF(AND(BE16=0,BC16>=$AC16,BC16>=$AD16)," แม้ว่า FYC รวมจะถึง "&TEXT($AD16,"#,###")&" บาท ของ Tier 2",IF(AND(BD16="Tier 1",BC16>=$AC16,BC16<$AD16)," ของ Tier 1 และ FYC รวมถึง "&TEXT($AC16,"#,###")&" บาท ของ Tier 1",IF(AND(BD16="Tier 1",BC16>=$AC16,BC16>=$AD16)," ของ Tier 1 แม้ว่า FYC รวมจะมากกว่า "&TEXT($AD16,"#,###")&" บาท ของ Tier 2",IF(AND(BD16="Tier 2",BC16>=$AC16,BC16>=$AD16)," ของ Tier 2 และ FYC รวมถึง "&TEXT($AD16,"#,###")&" บาท ของ Tier 2","")))))) -> ผลงานอนุมัติใหม่ถึง 100% ของ Tier 2 และ FYC รวมถึง 30,000 บาท ของ Tier 2 | BG16: 11 | BH16: =IF(BG16<=$P$4,SUM($BE$6:BE16),0) -> 0
B17: 3 | C17: โบนัสครึ่งปี ( MYB ) | D17: 40,000 - 60,000 | F17: 0.175 | G17: =IF(H6*$P$4/2>400000,"35%", IF(AND(H6*$P$4/2>300000,H6*$P$4/2<=400000),"32.5%", IF(AND(H6*$P$4/2>250000,H6*$P$4/2<=300000),"30%", IF(AND(H6*$P$4/2>200000,H6*$P$4/2<=250000),"27.5%", IF(AND(H6*$P$4/2>150000,H6*$P$4/2<=200000),"25%", IF(AND(H6*$P$4/2>100000,H6*$P$4/2<=150000),"22.5%", IF(AND(H6*$P$4/2>60000,H6*$P$4/2<=100000),"20%", IF(AND(H6*$P$4/2>40000,H6*$P$4/2<=60000),"17.5%", 1))))))))*(IF(H12<70%,0%,IF(AND(H12>=70%,H12<85%),100%,IF(H12>=85%,110%,)))) -> 0.35 | H17: =H6*$P$4*G17 -> 315000 | I17: =IF(J6*$Q$4/2>400000,"35%", IF(AND(J6*$Q$4/2>300000,J6*$Q$4/2<=400000),"32.5%", IF(AND(J6*$Q$4/2>250000,J6*$Q$4/2<=300000),"30%", IF(AND(J6*$Q$4/2>200000,J6*$Q$4/2<=250000),"27.5%", IF(AND(J6*$Q$4/2>150000,J6*$Q$4/2<=200000),"25%", IF(AND(J6*$Q$4/2>100000,J6*$Q$4/2<=150000),"22.5%", IF(AND(J6*$Q$4/2>60000,J6*$Q$4/2<=100000),"20%", IF(AND(J6*$Q$4/2>40000,J6*$Q$4/2<=60000),"17.5%", 1))))))))*(IF(J12<70%,0%,IF(AND(J12>=70%,J12<85%),100%,IF(J12>=85%,110%,)))) -> 0.35 | J17: =J6*$Q$4*I17 -> 299250 | K17: =IF(L6*$R$4/2>400000,"35%", IF(AND(L6*$R$4/2>300000,L6*$R$4/2<=400000),"32.5%", IF(AND(L6*$R$4/2>250000,L6*$R$4/2<=300000),"30%", IF(AND(L6*$R$4/2>200000,L6*$R$4/2<=250000),"27.5%", IF(AND(L6*$R$4/2>150000,L6*$R$4/2<=200000),"25%", IF(AND(L6*$R$4/2>100000,L6*$R$4/2<=150000),"22.5%", IF(AND(L6*$R$4/2>60000,L6*$R$4/2<=100000),"20%", IF(AND(L6*$R$4/2>40000,L6*$R$4/2<=60000),"17.5%", 1))))))))*(IF(L12<70%,0%,IF(AND(L12>=70%,L12<85%),100%,IF(L12>=85%,110%,)))) -> 0.35 | L17: =L6*$R$4*K17 -> 315000 | AA17: เดือน 12 | AC17: 15000 | AD17: 30000 | AF17: เดือนที่ 12 | AG17: =$H$6 -> 1200000 | AH17: 0 | AI17: =AG17+AH17 -> 1200000 | AJ17: =IF(AND(AG17>=$AD17*50%,AI17>=$AD17),"Tier 2",IF(AND(AG17>=$AC17*50%,AI17>=$AC17),"Tier 1",0)) -> Tier 2 | AK17: =IF(AJ17="Tier 2",20000,IF(AJ17="Tier 1",10000,IF(AND(OR(AF17="เดือนที่ 1",AF17="เดือนที่ 2"),AJ17=0,AG17>=$AB17),5000,0))) -> 20000 | AL17: ="ผลงานอนุมัติใหม่"&IF(OR(AND(AJ17="Tier 1",AG17>=$AC17),AND(AJ17="Tier 2",AG17>=$AD17)),"ถึง 100%",IF(OR(AND(AJ17=0,AG17>=$AC17*50%),AND(AJ17="Tier 1",AG17>=$AC17*50%),AND(AJ17="Tier 2",AG17>=$AD17*50%)),"ถึง 50%","ไม่ถึง 50%"))&IF(AND(AJ17=0,OR(AF17="เดือนที่ 1",AF17="เดือนที่ 2"),AI17>=$AC17*50%)," และ FYC รวมถึง "&TEXT(AI17,"#,###")&" เข้ากฎเกณฑ์ข้อ 4",IF(AND(AK17=0,AI17>=$AC17,AI17<$AD17)," แม้ว่า FYC รวมจะถึง "&TEXT($AC17,"#,###")&" บาท ของ Tier 1",IF(AND(AK17=0,AI17>=$AC17,AI17>=$AD17)," แม้ว่า FYC รวมจะถึง "&TEXT($AD17,"#,###")&" บาท ของ Tier 2",IF(AND(AJ17="Tier 1",AI17>=$AC17,AI17<$AD17)," ของ Tier 1 และ FYC รวมถึง "&TEXT($AC17,"#,###")&" บาท ของ Tier 1",IF(AND(AJ17="Tier 1",AI17>=$AC17,AI17>=$AD17)," ของ Tier 1 แม้ว่า FYC รวมจะมากกว่า "&TEXT($AD17,"#,###")&" บาท ของ Tier 2",IF(AND(AJ17="Tier 2",AI17>=$AC17,AI17>=$AD17)," ของ Tier 2 และ FYC รวมถึง "&TEXT($AD17,"#,###")&" บาท ของ Tier 2","")))))) -> ผลงานอนุมัติใหม่ถึง 100% ของ Tier 2 และ FYC รวมถึง 30,000 บาท ของ Tier 2 | AM17: 12 | AN17: =IF(AM17<=$P$4,SUM($AK$6:AK17),0) -> 0 | AP17: เดือนที่ 12 | AQ17: =$J$6 -> 1140000 | AR17: 0 | AS17: =AQ17+AR17 -> 1140000 | AT17: =IF(AND(AQ17>=$AD17*50%,AS17>=$AD17),"Tier 2",IF(AND(AQ17>=$AC17*50%,AS17>=$AC17),"Tier 1",0)) -> Tier 2 | AU17: =IF(AT17="Tier 2",20000,IF(AT17="Tier 1",10000,IF(AND(OR(AP17="เดือนที่ 1",AP17="เดือนที่ 2"),AT17=0,AQ17>=$AB17),5000,0))) -> 20000 | AV17: ="ผลงานอนุมัติใหม่"&IF(OR(AND(AT17="Tier 1",AQ17>=$AC17),AND(AT17="Tier 2",AQ17>=$AD17)),"ถึง 100%",IF(OR(AND(AT17=0,AQ17>=$AC17*50%),AND(AT17="Tier 1",AQ17>=$AC17*50%),AND(AT17="Tier 2",AQ17>=$AD17*50%)),"ถึง 50%","ไม่ถึง 50%"))&IF(AND(AT17=0,OR(AP17="เดือนที่ 1",AP17="เดือนที่ 2"),AS17>=$AC17*50%)," และ FYC รวมถึง "&TEXT(AS17,"#,###")&" เข้ากฎเกณฑ์ข้อ 4",IF(AND(AU17=0,AS17>=$AC17,AS17<$AD17)," แม้ว่า FYC รวมจะถึง "&TEXT($AC17,"#,###")&" บาท ของ Tier 1",IF(AND(AU17=0,AS17>=$AC17,AS17>=$AD17)," แม้ว่า FYC รวมจะถึง "&TEXT($AD17,"#,###")&" บาท ของ Tier 2",IF(AND(AT17="Tier 1",AS17>=$AC17,AS17<$AD17)," ของ Tier 1 และ FYC รวมถึง "&TEXT($AC17,"#,###")&" บาท ของ Tier 1",IF(AND(AT17="Tier 1",AS17>=$AC17,AS17>=$AD17)," ของ Tier 1 แม้ว่า FYC รวมจะมากกว่า "&TEXT($AD17,"#,###")&" บาท ของ Tier 2",IF(AND(AT17="Tier 2",AS17>=$AC17,AS17>=$AD17)," ของ Tier 2 และ FYC รวมถึง "&TEXT($AD17,"#,###")&" บาท ของ Tier 2","")))))) -> ผลงานอนุมัติใหม่ถึง 100% ของ Tier 2 และ FYC รวมถึง 30,000 บาท ของ Tier 2 | AW17: 12 | AX17: =IF(AW17<=$P$4,SUM($AU$6:AU17),0) -> 0 | AZ17: เดือนที่ 12 | BA17: =$L$6 -> 900000 | BB17: 0 | BC17: =BA17+BB17 -> 900000 | BD17: =IF(AND(BA17>=$AD17*50%,BC17>=$AD17),"Tier 2",IF(AND(BA17>=$AC17*50%,BC17>=$AC17),"Tier 1",0)) -> Tier 2 | BE17: =IF(BD17="Tier 2",20000,IF(BD17="Tier 1",10000,IF(AND(OR(AZ17="เดือนที่ 1",AZ17="เดือนที่ 2"),BD17=0,BA17>=$AB17),5000,0))) -> 20000 | BF17: ="ผลงานอนุมัติใหม่"&IF(OR(AND(BD17="Tier 1",BA17>=$AC17),AND(BD17="Tier 2",BA17>=$AD17)),"ถึง 100%",IF(OR(AND(BD17=0,BA17>=$AC17*50%),AND(BD17="Tier 1",BA17>=$AC17*50%),AND(BD17="Tier 2",BA17>=$AD17*50%)),"ถึง 50%","ไม่ถึง 50%"))&IF(AND(BD17=0,OR(AZ17="เดือนที่ 1",AZ17="เดือนที่ 2"),BC17>=$AC17*50%)," และ FYC รวมถึง "&TEXT(BC17,"#,###")&" เข้ากฎเกณฑ์ข้อ 4",IF(AND(BE17=0,BC17>=$AC17,BC17<$AD17)," แม้ว่า FYC รวมจะถึง "&TEXT($AC17,"#,###")&" บาท ของ Tier 1",IF(AND(BE17=0,BC17>=$AC17,BC17>=$AD17)," แม้ว่า FYC รวมจะถึง "&TEXT($AD17,"#,###")&" บาท ของ Tier 2",IF(AND(BD17="Tier 1",BC17>=$AC17,BC17<$AD17)," ของ Tier 1 และ FYC รวมถึง "&TEXT($AC17,"#,###")&" บาท ของ Tier 1",IF(AND(BD17="Tier 1",BC17>=$AC17,BC17>=$AD17)," ของ Tier 1 แม้ว่า FYC รวมจะมากกว่า "&TEXT($AD17,"#,###")&" บาท ของ Tier 2",IF(AND(BD17="Tier 2",BC17>=$AC17,BC17>=$AD17)," ของ Tier 2 และ FYC รวมถึง "&TEXT($AD17,"#,###")&" บาท ของ Tier 2","")))))) -> ผลงานอนุมัติใหม่ถึง 100% ของ Tier 2 และ FYC รวมถึง 30,000 บาท ของ Tier 2 | BG17: 12 | BH17: =IF(BG17<=$P$4,SUM($BE$6:BE17),0) -> 0
D18: 60,001 - 100,000 | F18: 0.2
D19: 100,001 - 150,000 | F19: 0.225
D20: 150,001 - 200,000 | F20: 0.25
D21: 200,001 - 250,000 | F21: 0.275
D22: 250,001 - 300,000 | F22: 0.3
D23: 300,001 - 400,000 | F23: 0.325 | AF23: รวม | AJ23: =SUM(AK6:AK17) -> 180000 | AP23: รวม | AT23: =SUM(AU6:AU17) -> 180000 | AZ23: รวม | BD23: =SUM(BE6:BE17) -> 180000
D24: 400,001 เป็นต้นไป | F24: 0.35
D25: ถ้า K2 >= 85% คิดเพิ่มเป็น 110%
B26: 4 | C26: ผลประโยชน์จากอาชีพ (CB) | G26: =IF(AND(H$6*H$11>=200000,H$12>=85%),SUM(H7:H10)*H$12*H$11*110%,IF(AND(H$6*H$11>=100000,H$12>=75%),SUM(H7:H10)*H$12*H$11*100%,0)) -> 607500 | I26: =IF(AND(J$6*J$11>=200000,J$12>=85%),SUM(J7:J10)*J$12*J$11*110%,IF(AND(J$6*J$11>=100000,J$12>=75%),SUM(J7:J10)*J$12*J$11*100%,0)) -> 540000 | K26: =IF(AND(L$6*L$11>=200000,L$12>=85%),SUM(L7:L10)*L$12*L$11*110%,IF(AND(L$6*L$11>=100000,L$12>=75%),SUM(L7:L10)*L$12*L$11*100%,0)) -> 562500 | O26: จำนวนราย | P26: 3 | Q26: 5 | R26: 10 | S26: ราย/เดือน
B27: 5 | C27: โบนัสตัวแทนใหม่ (NAB) | F27: ราย/3ด. | G27: =P26*3 -> 9 | H27: =IF(AND(G27>=5,H6*$P$4/4>=50000),15000,IF(AND(G27>=3,H6*$P$4/4>=20000),6000,0))+IF(AND(G27>=10,H6*$P$4/4>=100000),25000,IF(AND(G27>=5,H6*$P$4/4>=40000),10000,0)) -> 25000 | I27: =Q26*3 -> 15 | J27: =IF(AND(I27>=5,J6*$Q$4/4>=50000),15000,IF(AND(I27>=3,J6*$Q$4/4>=20000),6000,0))+IF(AND(I27>=10,J6*$Q$4/4>=100000),25000,IF(AND(I27>=5,J6*$Q$4/4>=40000),10000,0)) -> 40000 | K27: =R26*3 -> 30 | L27: =IF(AND(K27>=5,L6*$R$4/4>=50000),15000,IF(AND(K27>=3,L6*$R$4/4>=20000),6000,0))+IF(AND(K27>=10,L6*$R$4/4>=100000),25000,IF(AND(K27>=5,L6*$R$4/4>=40000),10000,0)) -> 40000
B28: 6 | C28: กองทุนเงินสะสม (SP) | G28: 0.05 | H28: =H6*$P$4*G28 -> 45000 | I28: 0.05 | J28: =J6*$Q$4*I28 -> 42750 | K28: 0.05 | L28: =L6*$R$4*K28 -> 45000
B29: รวมผลประโยชน์ AG | G29: =SUM(G5,H13,H17,G26,H27,H28) -> 3587500 | I29: =SUM(I5,J13,J17,I26,J27,J28) -> 3321250 | K29: =SUM(K5,L13,L17,K26,L27,L28) -> 2927500
B31: คุณวุฒิสวัสดิการ ปี 2567
B32: AG | C32: ผลประโยชน์ | E32: เกณฑ์และเงื่อนไข | G32: ประกันชีวิต | I32: สุขภาพ (GHS) | K32: สุขภาพ (OPD)
C33: แผน 1 | E33: FYC 100,000 บาท | G33: 100000 | I33: - | K33: -
C34: แผน 2 | E34: FYC 300,000 บาท | G34: 300000 | I34: 800 | K34: 500
C35: แผน 2 | E35: FYC 500,000 บาท | G35: 500000 | I35: 1400 | K35: 500

Sheet TIME
D2: ปี พ.ศ. | F2: ขณะนี้ท่านเหลือเวลาอยู่อีกเท่าไร ? | AC2: 30
D3: =IF(K3>K4,(K3-K5)+D5,0) -> 2624 | H3: =IF(K4>=1,"หากท่านมีอายุ",0) -> หากท่านมีอายุ | K3: 85 | L3: =IF(K4>=1,"ปี",0) -> ปี | M3: =IF(K3>=1,"=",0) -> = | O3: =K3*365 -> 31025 | Q3: =IF(O3>1,"วัน",0) -> วัน | AC3: 150
D4: =IF(K4>K5,(K4-K5)+D5,0) -> 2599 | H4: =IF(K5>=1,"เกษียณอายุ",0) -> เกษียณอายุ | K4: 60 | L4: =IF(K5>=1,"ปี",0) -> ปี
A5: =TODAY() -> 46119 | D5: 2569 | H5: ตอนนี้อายุ | K5: 30 | L5: ปี
B7: =IF(B8>=1,"อายุ / ปี",0) -> อายุ / ปี | C7: =IF(C8>=1,"เวลาที่ใช้ไป / วัน",0) -> เวลาที่ใช้ไป / วัน | E7: =IF(E8>=1,"เวลาที่เหลืออยู่ / วัน",0) -> เวลาที่เหลืออยู่ / วัน | I7: =IF(I8>1,"เหลือเวลาทำงาน / วัน",0) -> เหลือเวลาทำงาน / วัน | M7: =IF(M8>1,"เหลือเวลาหลังเกษียน/วัน",0) -> เหลือเวลาหลังเกษียน/วัน
B8: =K5 -> 30 | C8: =B8*365 -> 10950 | E8: =IF(K3>K5,(K3-B8)*365,0) -> 20075 | I8: =IF(K4>K5,(K4-B8)*365,0) -> 10950 | M8: =IF(K3>K4,E8-I8,0) -> 9125 | X8: Mobile Control
C9: =IF(B8>=1,"เหลือเวลา / ปี",0) -> เหลือเวลา / ปี | E9: =IF(K3>K5,K3-B8,0) -> 55 | I9: =IF(K4>K5,K4-B8,0) -> 30 | M9: =IF(K3>K4,K3-K4,0) -> 25 | X9: Auto
C11: =IF(K3>K4,"ต้องการเงินเกษียณเดือนละ",0) -> ต้องการเงินเกษียณเดือนละ | H11: =IF(X9="Auto",AC2*1000,Y11) -> 30000 | M11: =H11*12 -> 360000 | Q11: =IF(K3>K4,"/ปี",0) -> /ปี | S11: =M9 -> 25 | T11: =IF(S11>=1,"ปี",0) -> ปี | X11: เงินเกษียณ | Y11: 50000 | AA11: บาท
C12: =IF(K3>K4,"เงินใช้หลังเกษียณรวม",0) -> เงินใช้หลังเกษียณรวม | H12: =(H11/30)*M8 -> 9125000 | K12: บาท
C13: =IF(K4>K5,"วันนี้ต้องเก็บเงิน",0) -> วันนี้ต้องเก็บเงิน | H13: =(H12/I8)*30 -> 25000 | K13: =IF(K4>K5,"/เดือน",0) -> /เดือน | M13: =H13*12 -> 300000 | Q13: =IF(K4>K5,"/ปี",0) -> /ปี | S13: =I9 -> 30 | T13: =IF(S13>=1,"ปี",0) -> ปี
C14: ฝากธนาคารรายเดือน ดอกเบี้ย | H14: =IF(X9="Auto",AC3*0.0001,Y14) -> 0.015 | K14: / ปี | M14: =FV(H14*0.85/12,S13*12,-H13) -> 10956405 | Q14: บาท | X14: ดอกเบี้ย | Y14: 0.02
A15: =IF(K5<=55,"ขอเสนอแนะนำโครงการของบริษัท ชับบ์ ไลฟ์ แอสชัวรันซ์ จำกัด (มหาชน)",0) -> ขอเสนอแนะนำโครงการของบริษัท ชับบ์ ไลฟ์ แอสชัวรันซ์ จำกัด (มหาชน)

Sheet PA
G2: PA | H2: PAS1 | AB2: แบบ | AC2: ทุน | AD2: รายปี | AE2: รายเดือน | AF2: Com
H3: =IF(AND(L3>=0,L3<=60),VLOOKUP(H2,AB3:AE20,2,0),"อายุทำไม่ได้") -> 275000 | I3: Baht | J3: Age | L3: =TIME!K5 -> 30 | AB3: - | AD3: 0 | AE3: 0 | AF3: 0
